Workbook

Sheet TEG_Syncronous_Pipeline_回路規模
A1: TEGパターン(N=Reg段、M＝Logic段) | B1: Registers | C1: LUTs | D1: Slices | G1: TEGパターン | H1: Registers | I1: Implementation LUTs | J1: Slices | K1: Synthesis LUTs
A2: 100N16M | B2: 3351 | C2: 30226 | D2: 7759 | G2: 400N5M | H2: 9786 | I2: 32416 | J2: 8424 | K2: 48094
A3: 100N12M | B3: 3351 | C3: 26451 | D3: 7707 | G3: 300N4M | H3: 9786 | I3: 30884 | J3: 8426 | K3: 38497
A4: 100N8M | B4: 3351 | C4: 22184 | D4: 7431 | G4: 300N3M | H4: 9786 | I4: 22896 | J4: 8408 | K4: 28897
A5: 100N4M | B5: 3351 | C5: 12566 | D5: 5013 | G5: 300N2M | H5: 9786 | I5: 15328 | J5: 8363 | K5: 19297
A6: 100N2M | B6: 3351 | C6: 6432 | D6: 3969 | G6: 300N1M | H6: 9786 | I6: 7830 | J6: 8270 | K6: 9697
A7: 100N1M | B7: 3351 | C7: 3255 | D7: 3650 | G7: 300N0M | H7: 9786 | I7: 96 | J7: 6553
A8: 100N0M | B8: 3351 | C8: 96 | D8: 3283
A10: TEGパターン | B10: Implementation LUTs | C10: Assunption LU s | D10: Synthesis LUTs
A11: 100N16M | B11: 30226 | C11: =16*32*100 -> 51200 | D11: 51293
A12: 100N12M | B12: 26451 | C12: =12*32*100 -> 38400 | D12: 38497
A13: 100N8M | B13: 22184 | C13: =8*32*100 -> 25600 | D13: 25697
A14: 100N4M | B14: 12566 | C14: =4*32*100 -> 12800 | D14: 12897
A15: 100N2M | B15: 6432 | C15: =2*32*100 -> 6400 | D15: 6497
A16: 100N1M | B16: 3255 | C16: =1*32*100 -> 3200 | D16: 3297
B18: Implementation LUTs | C18: Assunption LUT s | D18: Synthesis LUTs | E18: Reg | F18: Slice
A19: 400N3M | B19: 28734 | C19: =3*32*400 -> 38400 | D19: 38494 | E19: 12986 | F19: 7690
A20: 400N2M | B20: 25574 | C20: =2*32*400 -> 25600 | D20: 25697 | E20: 12986 | F20: 7693
A22: 200N8M | B22: 31691 | C22: =8*32*200 -> 51200 | D22: 51293 | E22: 6586 | F22: 8176
A23: 200N4M | B23: 22871 | C23: =4*32*200 -> 25600 | D23: 25697 | E23: 6586 | F23: 8030
A25: 50N16M | B25: 16895 | C25: =16*32*50 -> 25600 | E25: 1786 | F25: 4416
A26: 50N8M | B26: 11467 | C26: =8*32*50 -> 12800 | E26: 1786 | F26: 4064

Sheet 電力データ_0610までに取得分
A1: 旧方法 | B1: 43 | C1: 35 | D1: 40 | E1: 30 | F1: 25 | G1: 20 | L1: 新しい方法 | M1: 0.40625 | N1: 0.40972222 | O1: 0.038194444 | P1: 0.39930556 | R1: 0.39583333 | U1: 0.39583333 | Z1: 0.375 | AB1: 62.5MHz | AH1: 125MHz | AI1: 0.017361111 | AJ1: 0.40625 | AK1: 0.39930556
B2: 100N16M | C2: 100N12M | D2: 100N8M | E2: 100N4M | F2: 100N2M | G2: 100N1M | L2: RouteR社 | M2: 100N16M | N2: 100N12M | O2: 100N8M | P2: 100N4M | Q2: 100N2M | R2: 100N1M | T2: COOWOO社 | U2: 100N16M | V2: 100N12M | W2: 100N8M | X2: 100N4M | Y2: 100N2M | Z2: 100N1M | AB2: RouteR社 | AC2: 300N4M | AD2: 300N3M | AE2: 300N2M | AF2: 300N1M | AH2: RouteR社 | AI2: 300N4M | AJ2: 300N3M | AK2: 300N2M | AL2: 300N1M
A3: 0 | B3: 1.514 | C3: 1.512 | D3: 1.502 | E3: 1.512 | F3: 1.509 | G3: 1.512 | L3: 0 | M3: 1.952 | N3: 1.879 | O3: 1.793 | P3: 1.705 | Q3: 1.666 | R3: 1.659 | T3: 0 | U3: 1.911 | V3: 1.833 | W3: 1.736 | X3: 1.645 | Y3: 1.607 | Z3: 1.585 | AB3: 0 | AH3: 0 | AI3: 2.435 | AJ3: 2.347 | AK3: 2.207 | AL3: 2.051
A4: 0 | B4: 1.514 | C4: 1.512 | D4: 1.522 | E4: 1.522 | F4: 1.509 | G4: 1.512 | L4: 0 | M4: 1.965 | N4: 1.879 | O4: 1.801 | P4: 1.705 | Q4: 1.653 | R4: 1.649 | T4: 0 | U4: 1.911 | V4: 1.833 | W4: 1.736 | X4: 1.645 | Y4: 1.607 | Z4: 1.585 | AB4: 0 | AH4: 0 | AI4: 2.43 | AJ4: 2.347 | AK4: 2.207 | AL4: 2.064
A5: 1 | B5: 1.514 | C5: 1.512 | D5: 1.522 | E5: 1.522 | F5: 1.502 | G5: 1.512 | L5: 1 | M5: 1.962 | N5: 1.879 | O5: 1.796 | P5: 1.702 | Q5: 1.666 | R5: 1.649 | T5: 1 | U5: 1.911 | V5: 1.833 | W5: 1.736 | X5: 1.648 | Y5: 1.615 | Z5: 1.595 | AB5: 1 | AH5: 1 | AI5: 2.43 | AJ5: 2.347 | AK5: 2.211 | AL5: 2.064
A6: 1 | B6: 1.504 | C6: 1.519 | D6: 1.502 | E6: 1.512 | F6: 1.502 | G6: 1.512 | L6: 1 | M6: 1.965 | N6: 1.886 | O6: 1.801 | P6: 1.715 | Q6: 1.666 | R6: 1.656 | T6: 1 | U6: 1.916 | V6: 1.833 | W6: 1.736 | X6: 1.648 | Y6: 1.615 | Z6: 1.595 | AB6: 1 | AH6: 1 | AI6: 2.44 | AJ6: 2.347 | AK6: 2.197 | AL6: 2.064
A7: 2 | B7: 1.504 | C7: 1.519 | D7: 1.512 | E7: 1.512 | F7: 1.502 | G7: 1.512 | L7: 2 | M7: 1.975 | N7: 1.889 | O7: 1.801 | P7: 1.705 | Q7: 1.656 | R7: 1.656 | T7: 2 | U7: 1.916 | V7: 1.833 | W7: 1.736 | X7: 1.648 | Y7: 1.615 | Z7: 1.585 | AB7: 2 | AH7: 2 | AI7: 2.445 | AJ7: 2.347 | AK7: 2.211 | AL7: 2.061
A8: 2 | B8: 1.504 | C8: 1.509 | D8: 1.509 | E8: 1.499 | F8: 1.502 | G8: 1.512 | L8: 2 | M8: 1.982 | N8: 1.89 | O8: 1.896 | P8: 1.702 | Q8: 1.666 | R8: 1.666 | T8: 2 | U8: 1.916 | V8: 1.833 | W8: 1.736 | X8: 1.648 | Y8: 1.615 | Z8: 1.585 | AB8: 2 | AH8: 2 | AI8: 2.43 | AJ8: 2.347 | AK8: 2.211 | AL8: 2.064
A9: 3 | B9: 1.504 | C9: 1.512 | D9: 1.509 | E9: 1.499 | F9: 1.512 | G9: 1.509 | L9: 3 | M9: 1.955 | N9: 1.889 | O9: 1.798 | P9: 1.712 | Q9: 1.656 | R9: 1.656 | T9: 3 | U9: 1.916 | V9: 1.833 | W9: 1.736 | X9: 1.648 | Y9: 1.605 | Z9: 1.585 | AB9: 3 | AH9: 3 | AI9: 2.44 | AJ9: 2.343 | AK9: 2.2 | AL9: 2.064
A10: 3 | B10: 1.512 | C10: 1.512 | D10: 1.499 | E10: 1.512 | F10: 1.509 | G10: 1.512 | L10: 3 | M10: 1.965 | N10: 1.896 | O10: 1.801 | P10: 1.712 | Q10: 1.666 | R10: 1.656 | T10: 3 | U10: 1.916 | V10: 1.823 | W10: 1.736 | X10: 1.648 | Y10: 1.605 | Z10: 1.585 | AB10: 3 | AH10: 3 | AI10: 2.455 | AJ10: 2.352 | AK10: 2.211 | AL10: 2.064
A11: 4 | B11: 1.504 | C11: 1.499 | D11: 1.512 | E11: 1.512 | F11: 1.512 | G11: 1.512 | L11: 4 | M11: 1.965 | N11: 1.889 | O11: 1.801 | P11: 1.705 | Q11: 1.656 | R11: 1.646 | T11: 4 | U11: 1.916 | V11: 1.823 | W11: 1.736 | X11: 1.645 | Y11: 1.605 | Z11: 1.585 | AB11: 4 | AH11: 4 | AI11: 2.455 | AJ11: 2.339 | AK11: 2.211 | AL11: 2.061
A12: 4 | B12: 1.504 | C12: 1.512 | D12: 1.512 | E12: 1.512 | F12: 1.502 | G12: 1.512 | L12: 4 | M12: 1.965 | N12: 1.889 | O12: 1.801 | P12: 1.705 | Q12: 1.656 | R12: 1.656 | T12: 4 | U12: 1.916 | V12: 1.833 | W12: 1.736 | X12: 1.645 | Y12: 1.605 | Z12: 1.585 | AB12: 4 | AH12: 4 | AI12: 2.445 | AJ12: 2.339 | AK12: 2.211 | AL12: 2.061
A13: 5 | B13: 1.504 | C13: 1.512 | D13: 1.509 | E13: 1.512 | F13: 1.502 | G13: 1.502 | L13: 5 | M13: 1.975 | N13: 1.886 | O13: 1.798 | P13: 1.705 | Q13: 1.656 | R13: 1.646 | T13: 5 | U13: 1.911 | V13: 1.833 | W13: 1.736 | X13: 1.648 | Y13: 1.605 | Z13: 1.585 | AB13: 5 | AH13: 5 | AI13: 2.44 | AJ13: 2.333 | AK13: 2.2 | AL13: 2.051
A14: 5 | B14: 1.504 | C14: 1.512 | D14: 1.509 | E14: 1.512 | F14: 1.509 | G14: 1.525 | L14: 5 | M14: 1.965 | N14: 1.886 | O14: 1.796 | P14: 1.702 | Q14: 1.666 | R14: 1.646 | T14: 5 | U14: 1.911 | V14: 1.833 | W14: 1.736 | X14: 1.648 | Y14: 1.605 | Z14: 1.585 | AB14: 5 | AH14: 5 | AI14: 2.44 | AJ14: 2.348 | AK14: 2.2 | AL14: 2.051
... A64: 30 | B64: 1.494 | C64: 1.522 | D64: 1.512 | E64: 1.512 | F64: 1.502 | G64: 1.502 | L64: 30 | M64: 1.962 | N64: 1.889 | O64: 1.801 | P64: 1.705 | Q64: 1.656 | R64: 1.656 | T64: 30 | U64: 1.916 | V64: 1.833 | W64: 1.742 | X64: 1.645 | Y64: 1.607 | Z64: 1.585 | AB64: 30 | AH64: 30 | AI64: 2.43 | AJ64: 2.347 | AK64: 2.2 | AL64: 2.064
B65: =AVERAGE(B3:B64) -> 1.5054032 | C65: =AVERAGE(C3:C64) -> 1.5122097 | D65: =AVERAGE(D3:D64) -> 1.5075323 | E65: =AVERAGE(E3:E64) -> 1.512371 | F65: =AVERAGE(F3:F64) -> 1.5099516 | G65: =AVERAGE(G3:G64) -> 1.5109194 | M65: =AVERAGE(M3:M64) -> 1.9663226 | N65: =AVERAGE(N3:N64) -> 1.8869839 | O65: =AVERAGE(O3:O64) -> 1.798871 | P65: =AVERAGE(P3:P64) -> 1.7064839 | Q65: =AVERAGE(Q3:Q64) -> 1.6622097 | R65: =AVERAGE(R3:R64) -> 1.6520161 | U65: =AVERAGE(U3:U64) -> 1.9135 | V65: =AVERAGE(V3:V64) -> 1.8320323 | W65: =AVERAGE(W3:W64) -> 1.7371613 | X65: =AVERAGE(X3:X64) -> 1.6475645 | Y65: =AVERAGE(Y3:Y64) -> 1.6071613 | Z65: =AVERAGE(Z3:Z64) -> 1.5851855 | AI65: =AVERAGE(AI3:AI64) -> 2.4355806 | AJ65: =AVERAGE(AJ3:AJ64) -> 2.3450484 | AK65: =AVERAGE(AK3:AK64) -> 2.2052903 | AL65: =AVERAGE(AL3:AL64) -> 2.0589516
A66: 室温 | B66: 27℃ | C66: 28℃ | D66: 28℃ | E66: 28℃ | F66: 28℃ | G66: 27℃ | L66: 室温
AE79: 62.5MHz | AF79: 125MHz
AD80: 300N4M | AE80: 1.928 | AF80: 2.4355
AD81: 300N3M | AE81: 1.9 | AF81: 2.345
AD82: 300N2M | AE82: 1.818 | AF82: 2.2052
AD83: 300N1M | AE83: 1.776 | AF83: 2.0589
AA86: 1.928 | AB86: 1.9 | AC86: 1.818 | AD86: 1.776 | AG86: 2.4355 | AH86: 2.345 | AI86: 2.2052 | AJ86: 2.0589
L95: RouteR社 | M95: COOWOO社 | N95: 推定
K96: 100N16M | L96: =M65 -> 1.9663226 | M96: =U65 -> 1.9135 | N96: 0.542 | O96: =L96-N96 -> 1.4243226 | P96: =M96-N96 -> 1.3715 | Q96: =L96-M96 -> 0.052822581
K97: 100N12M | L97: =N65 -> 1.8869839 | M97: =V65 -> 1.8320323 | N97: 0.466 | O97: =L97-N97 -> 1.4209839 | P97: =M97-N97 -> 1.3660323 | Q97: =L97-M97 -> 0.054951613
K98: 100N8M | L98: =O65 -> 1.798871 | M98: =W65 -> 1.7371613 | N98: 0.368 | O98: =L98-N98 -> 1.430871 | P98: =M98-N98 -> 1.3691613 | Q98: =L98-M98 -> 0.061709677
K99: 100N4M | L99: =P65 -> 1.7064839 | M99: =X65 -> 1.6475645 | N99: 0.27 | O99: =L99-N99 -> 1.4364839 | P99: =M99-N99 -> 1.3775645 | Q99: =L99-M99 -> 0.058919355
K100: 100N2M | L100: =Q65 -> 1.6622097 | M100: =Y65 -> 1.6071613 | N100: 0.22 | O100: =L100-N100 -> 1.4422097 | P100: =M100-N100 -> 1.3871613 | Q100: =L100-M100 -> 0.055048387
K101: 100N1M | L101: =R65 -> 1.6520161 | M101: =Z65 -> 1.5851855 | N101: 0.197 | O101: =L101-N101 -> 1.4550161 | P101: =M101-N101 -> 1.3881855 | Q101: =L101-M101 -> 0.066830645

Sheet 電力データ_0610以降_100N
B1: データ | L1: InputData停止 | V1: 配置配線固定なし
B2: RouteR社 | C2: 100N16M | D2: 100N12M | E2: 100N8M | F2: 100N4M | G2: 100N2M | H2: 100N1M | I2: 100N0M | L2: RouteR社 | M2: 100N16M | N2: 100N12M | O2: 100N8M | P2: 100N4M | Q2: 100N2M | R2: 100N1M | V2: RouteR社 | W2: 100N16M | X2: 100N12M | Y2: 100N8M | Z2: 100N4M | AA2: 100N2M | AB2: 100N1M
B3: 0 | C3: 1.886 | D3: 1.815 | E3: 1.726 | F3: 1.636 | G3: 1.585 | H3: 1.572 | I3: 1.552 | L3: 0 | M3: 1.512 | N3: 1.515 | O3: 1.509 | P3: 1.499 | Q3: 1.504 | R3: 1.504 | V3: 0 | Y3: 1.722
B4: 0 | C4: 1.899 | D4: 1.815 | E4: 1.719 | F4: 1.633 | G4: 1.585 | H4: 1.575 | I4: 1.552 | L4: 0 | M4: 1.512 | N4: 1.515 | O4: 1.496 | P4: 1.499 | Q4: 1.504 | R4: 1.504 | V4: 0 | Y4: 1.729
B5: 1 | C5: 1.896 | D5: 1.815 | E5: 1.719 | F5: 1.636 | G5: 1.578 | H5: 1.567 | I5: 1.55 | L5: 1 | M5: 1.512 | N5: 1.492 | O5: 1.509 | P5: 1.499 | Q5: 1.517 | R5: 1.501 | V5: 1 | Y5: 1.722
B6: 1 | C6: 1.896 | D6: 1.818 | E6: 1.729 | F6: 1.636 | G6: 1.598 | H6: 1.575 | I6: 1.552 | L6: 1 | M6: 1.512 | N6: 1.492 | O6: 1.509 | P6: 1.499 | Q6: 1.504 | R6: 1.501 | V6: 1 | Y6: 1.719
B7: 2 | C7: 1.889 | D7: 1.805 | E7: 1.729 | F7: 1.633 | G7: 1.598 | H7: 1.575 | I7: 1.552 | L7: 2 | M7: 1.512 | N7: 1.502 | O7: 1.499 | P7: 1.509 | Q7: 1.494 | R7: 1.501 | V7: 2 | Y7: 1.719
B8: 2 | C8: 1.886 | D8: 1.805 | E8: 1.729 | F8: 1.633 | G8: 1.598 | H8: 1.572 | I8: 1.552 | L8: 2 | M8: 1.512 | N8: 1.502 | O8: 1.499 | P8: 1.506 | Q8: 1.494 | R8: 1.494 | V8: 2 | Y8: 1.719
B9: 3 | C9: 1.896 | D9: 1.815 | E9: 1.719 | F9: 1.633 | G9: 1.588 | H9: 1.57 | I9: 1.54 | L9: 3 | M9: 1.512 | N9: 1.502 | O9: 1.499 | P9: 1.496 | Q9: 1.494 | R9: 1.494 | V9: 3 | Y9: 1.719
B10: 3 | C10: 1.896 | D10: 1.815 | E10: 1.729 | F10: 1.633 | G10: 1.588 | H10: 1.57 | I10: 1.552 | L10: 3 | M10: 1.512 | N10: 1.512 | O10: 1.509 | P10: 1.496 | Q10: 1.504 | R10: 1.494 | V10: 3 | Y10: 1.729
B11: 4 | C11: 1.889 | D11: 1.815 | E11: 1.719 | F11: 1.643 | G11: 1.588 | H11: 1.56 | I11: 1.552 | L11: 4 | M11: 1.512 | N11: 1.502 | O11: 1.519 | P11: 1.509 | Q11: 1.504 | R11: 1.506 | V11: 4 | Y11: 1.719
B12: 4 | C12: 1.899 | D12: 1.805 | E12: 1.719 | F12: 1.633 | G12: 1.588 | H12: 1.572 | I12: 1.542 | L12: 4 | M12: 1.512 | N12: 1.502 | O12: 1.509 | P12: 1.496 | Q12: 1.496 | R12: 1.504 | V12: 4 | Y12: 1.722
B13: 5 | C13: 1.945 | D13: 1.805 | E13: 1.722 | F13: 1.643 | G13: 1.598 | H13: 1.57 | I13: 1.54 | L13: 5 | M13: 1.499 | N13: 1.512 | O13: 1.509 | P13: 1.509 | Q13: 1.494 | R13: 1.509 | V13: 5 | Y13: 1.719
B14: 5 | C14: 1.889 | D14: 1.815 | E14: 1.729 | F14: 1.633 | G14: 1.585 | H14: 1.567 | I14: 1.54 | L14: 5 | M14: 1.509 | N14: 1.492 | O14: 1.509 | P14: 1.499 | Q14: 1.494 | R14: 1.506 | V14: 5 | Y14: 1.719
... B64: 30 | C64: 1.899 | D64: 1.815 | E64: 1.726 | F64: 1.646 | G64: 1.598 | H64: 1.575 | I64: 1.552 | L64: 30 | M64: 1.512 | N64: 1.515 | O64: 1.506 | P64: 1.506 | Q64: 1.504 | R64: 1.506 | V64: 30 | Y64: 1.732
B65: 平均 | C65: =AVERAGE(C3:C64) -> 1.8938226 | D65: =AVERAGE(D3:D64) -> 1.8137097 | E65: =AVERAGE(E3:E64) -> 1.7232742 | F65: =AVERAGE(F3:F64) -> 1.6362419 | G65: =AVERAGE(G3:G64) -> 1.5922097 | H65: =AVERAGE(H3:H64) -> 1.5545 | I65: =AVERAGE(I3:I64) -> 1.5473065 | M65: =AVERAGE(M3:M64) -> 1.5085 | N65: =AVERAGE(N3:N64) -> 1.5056774 | O65: =AVERAGE(O3:O64) -> 1.5056452 | P65: =AVERAGE(P3:P64) -> 1.5045806 | Q65: =AVERAGE(Q3:Q64) -> 1.5017419 | R65: =AVERAGE(R3:R64) -> 1.502871 | Y65: =AVERAGE(Y3:Y64) -> 1.7223871
A69: ①
B70: グラフ | C70: (1)テスト回路動作時電力 | M70: (2)テスト回路ごとに電力とLUT数を比較
C71: 100N16M | D71: =1.893823 -> 1.893823 | M71: (実測) | O71: LUT | P71: POWER
C72: 100N12M | D72: 1.81371 | N72: 16M-12M | O72: =TEG_Syncronous_Pipeline_回路規模!$C$2-TEG_Syncronous_Pipeline_回路規模!$C$3 -> 3775 | P72: =$C$65-$D$65 -> 0.080112903
C73: 100N8M | D73: 1.723274 | N73: 16M-8M | O73: =TEG_Syncronous_Pipeline_回路規模!$C$2-TEG_Syncronous_Pipeline_回路規模!$C$4 -> 8042 | P73: =$C$65-$E$65 -> 0.17054839
C74: 100N4M | D74: 1.636242 | N74: 16M-4M | O74: =TEG_Syncronous_Pipeline_回路規模!$C$2-TEG_Syncronous_Pipeline_回路規模!$C$5 -> 17660 | P74: =$C$65-$F$65 -> 0.25758065
C75: 100N2M | D75: 1.59221 | N75: 16M-2M | O75: =TEG_Syncronous_Pipeline_回路規模!$C$2-TEG_Syncronous_Pipeline_回路規模!$C$6 -> 23794 | P75: =$C$65-$G$65 -> 0.3016129
C76: 100N1M | D76: 1.5545 | N76: 16M-1M | O76: =TEG_Syncronous_Pipeline_回路規模!$C$2-TEG_Syncronous_Pipeline_回路規模!$C$7 -> 26971 | P76: =$C$65-$H$65 -> 0.33932258
N77: 12M -8M | O77: =TEG_Syncronous_Pipeline_回路規模!$C$3-TEG_Syncronous_Pipeline_回路規模!$C$4 -> 4267 | P77: =$D$65-$E$65 -> 0.090435484
N78: 12M-4M | O78: =TEG_Syncronous_Pipeline_回路規模!$C$3-TEG_Syncronous_Pipeline_回路規模!$C$5 -> 13885 | P78: =$D$65-$F$65 -> 0.17746774
N79: 12M-2M | O79: =TEG_Syncronous_Pipeline_回路規模!$C$3-TEG_Syncronous_Pipeline_回路規模!$C$6 -> 20019 | P79: =$D$65-$G$65 -> 0.2215
N80: 12M-1M | O80: =TEG_Syncronous_Pipeline_回路規模!$C$3-TEG_Syncronous_Pipeline_回路規模!$C$7 -> 23196 | P80: =$D$65-$H$65 -> 0.25920968
N81: 8M-4M | O81: =TEG_Syncronous_Pipeline_回路規模!$C$4-TEG_Syncronous_Pipeline_回路規模!$C$5 -> 9618 | P81: =$E$65-$F$65 -> 0.087032258
N82: 8M-2M | O82: =TEG_Syncronous_Pipeline_回路規模!$C$4-TEG_Syncronous_Pipeline_回路規模!$C$6 -> 15752 | P82: =$E$65-$G$65 -> 0.13106452
N83: 8M-1M | O83: =TEG_Syncronous_Pipeline_回路規模!$C$4-TEG_Syncronous_Pipeline_回路規模!$C$7 -> 18929 | P83: =$E$65-$H$65 -> 0.16877419
N84: 4M-2M | O84: =TEG_Syncronous_Pipeline_回路規模!$C$5-TEG_Syncronous_Pipeline_回路規模!$C$6 -> 6134 | P84: =$F$65-$G$65 -> 0.044032258
N85: 4M-1M | O85: =TEG_Syncronous_Pipeline_回路規模!$C$5-TEG_Syncronous_Pipeline_回路規模!$C$7 -> 9311 | P85: =$F$65-$H$65 -> 0.081741935
N86: 2M-1M | O86: =TEG_Syncronous_Pipeline_回路規模!$C$6-TEG_Syncronous_Pipeline_回路規模!$C$7 -> 3177 | P86: =$G$65-$H$65 -> 0.037709677
A89: ②
A90: 2024/6/19に取得したデータ
B91: (1)テスト回路動作時電力 | F91: (2)テスト回路ごとに電力とLUT数を比較
C92: do | G92: LUT | H92: POWER
B93: 100N16M | C93: =$C$65-$M$65 -> 0.38532258 | F93: 16M-12M | G93: =TEG_Syncronous_Pipeline_回路規模!$C$2-TEG_Syncronous_Pipeline_回路規模!$C$3 -> 3775 | H93: =$C$93-$C$94 -> 0.077290323
B94: 100N12M | C94: =$D$65-$N$65 -> 0.30803226 | F94: 16M-8M | G94: =TEG_Syncronous_Pipeline_回路規模!$C$2-TEG_Syncronous_Pipeline_回路規模!$C$4 -> 8042 | H94: =$C$93-$C$95 -> 0.16769355
...

Sheet 電力データ0610以降_300N
A1: 62.5MHz | B1: 動作時 | C1: 300N4M | D1: 300N3M | E1: 300N2M | F1: 300N1M | G1: 300N0M | H1: 停止時 | I1: 300N4M | J1: 300N3M | K1: 300N2M | L1: 300N1M | N1: 125MHz | O1: 動作時 | P1: 300N4M | Q1: 300N3M | R1: 300N2M | S1: 300N1M | T1: 300N0M | U1: 停止時 | V1: 300N4M | W1: 300N3M | X1: 300N2M | Y1: 300N1M
B2: 0 | C2: 1.896 | D2: 1.855 | E2: 1.769 | F2: 1.702 | G2: 1.633 | H2: 0 | I2: 1.537 | J2: 1.547 | K2: 1.532 | L2: 1.537 | O2: 0 | P2: 2.329 | Q2: 2.227 | R2: 2.094 | S2: 2.068 | T2: 1.808 | U2: 0 | V2: 1.626 | W2: 1.627 | X2: 1.62 | Y2: 1.656
B3: 0 | C3: 1.896 | D3: 1.859 | E3: 1.769 | F3: 1.699 | G3: 1.64 | H3: 0 | I3: 1.534 | J3: 1.547 | K3: 1.532 | L3: 1.526 | O3: 0 | P3: 2.323 | Q3: 2.223 | R3: 2.081 | S3: 2.068 | T3: 1.805 | U3: 0 | V3: 1.626 | W3: 1.62 | X3: 1.62 | Y3: 1.666
B4: 1 | C4: 1.886 | D4: 1.849 | E4: 1.766 | F4: 1.702 | G4: 1.63 | H4: 1 | I4: 1.54 | J4: 1.547 | K4: 1.542 | L4: 1.526 | O4: 1 | P4: 2.333 | Q4: 2.223 | R4: 2.084 | S4: 2.064 | T4: 1.798 | U4: 1 | V4: 1.626 | W4: 1.62 | X4: 1.62 | Y4: 1.666
B5: 1 | C5: 1.886 | D5: 1.855 | E5: 1.776 | F5: 1.702 | G5: 1.63 | H5: 1 | I5: 1.54 | J5: 1.547 | K5: 1.542 | L5: 1.526 | O5: 1 | P5: 2.333 | Q5: 2.227 | R5: 2.081 | S5: 2.064 | T5: 1.798 | U5: 1 | V5: 1.626 | W5: 1.625 | X5: 1.623 | Y5: 1.666
B6: 2 | C6: 1.886 | D6: 1.845 | E6: 1.78 | F6: 1.702 | G6: 1.63 | H6: 2 | I6: 1.527 | J6: 1.55 | K6: 1.542 | L6: 1.526 | O6: 2 | P6: 2.323 | Q6: 2.227 | R6: 2.081 | S6: 2.064 | T6: 1.808 | U6: 2 | V6: 1.623 | W6: 1.638 | X6: 1.623 | Y6: 1.659
B7: 2 | C7: 1.886 | D7: 1.845 | E7: 1.766 | F7: 1.699 | G7: 1.64 | H7: 2 | I7: 1.537 | J7: 1.54 | K7: 1.542 | L7: 1.526 | O7: 2 | P7: 2.343 | Q7: 2.227 | R7: 2.091 | S7: 2.068 | T7: 1.808 | U7: 2 | V7: 1.623 | W7: 1.62 | X7: 1.613 | Y7: 1.666
B8: 3 | C8: 1.882 | D8: 1.849 | E8: 1.769 | F8: 1.699 | G8: 1.63 | H8: 3 | I8: 1.527 | J8: 1.54 | K8: 1.532 | L8: 1.544 | O8: 3 | P8: 2.323 | Q8: 2.223 | R8: 2.084 | S8: 2.064 | T8: 1.808 | U8: 3 | V8: 1.623 | W8: 1.627 | X8: 1.62 | Y8: 1.666
B9: 3 | C9: 1.882 | D9: 1.869 | E9: 1.766 | F9: 1.702 | G9: 1.63 | H9: 3 | I9: 1.527 | J9: 1.54 | K9: 1.529 | L9: 1.544 | O9: 3 | P9: 2.323 | Q9: 2.227 | R9: 2.084 | S9: 2.058 | T9: 1.808 | U9: 3 | V9: 1.621 | W9: 1.63 | X9: 1.613 | Y9: 1.656
B10: 4 | C10: 1.886 | D10: 1.835 | E10: 1.766 | F10: 1.699 | G10: 1.64 | H10: 4 | I10: 1.527 | J10: 1.529 | K10: 1.539 | L10: 1.534 | O10: 4 | P10: 2.333 | Q10: 2.223 | R10: 2.094 | S10: 2.058 | T10: 1.808 | U10: 4 | V10: 1.636 | W10: 1.62 | X10: 1.623 | Y10: 1.656
B11: 4 | C11: 1.893 | D11: 1.838 | E11: 1.776 | F11: 1.699 | G11: 1.64 | H11: 4 | I11: 1.537 | J11: 1.529 | K11: 1.539 | L11: 1.537 | O11: 4 | P11: 2.333 | Q11: 2.22 | R11: 2.084 | S11: 2.068 | T11: 1.798 | U11: 4 | V11: 1.626 | W11: 1.62 | X11: 1.613 | Y11: 1.656
B12: 5 | C12: 1.886 | D12: 1.855 | E12: 1.776 | F12: 1.699 | G12: 1.64 | H12: 5 | I12: 1.537 | J12: 1.54 | K12: 1.529 | L12: 1.544 | O12: 5 | P12: 2.333 | Q12: 2.217 | R12: 2.081 | S12: 2.051 | T12: 1.801 | U12: 5 | V12: 1.616 | W12: 1.627 | X12: 1.613 | Y12: 1.676
B13: 5 | C13: 1.882 | D13: 1.835 | E13: 1.776 | F13: 1.709 | G13: 1.64 | H13: 5 | I13: 1.54 | J13: 1.529 | K13: 1.532 | L13: 1.532 | O13: 5 | P13: 2.333 | Q13: 2.217 | R13: 2.081 | S13: 2.054 | T13: 1.801 | U13: 5 | V13: 1.616 | W13: 1.627 | X13: 1.623 | Y13: 1.656
... B63: 30 | C63: 1.886 | D63: 1.855 | E63: 1.766 | F63: 1.712 | G63: 1.633 | H63: 30 | I63: 1.54 | J63: 1.54 | K63: 1.532 | L63: 1.537 | O63: 30 | P63: 2.329 | Q63: 2.223 | R63: 2.081 | S63: 2.054 | T63: 1.798 | U63: 30 | V63: 1.613 | W63: 1.63 | X63: 1.626 | Y63: 1.666
C64: =AVERAGE(C2:C63) -> 1.885 | D64: =AVERAGE(D2:D63) -> 1.8492742 | E64: =AVERAGE(E2:E63) -> 1.7670484 | F64: =AVERAGE(F2:F63) -> 1.7039194 | G64: =AVERAGE(G2:G63) -> 1.634371 | I64: =AVERAGE(I2:I63) -> 1.5348871 | J64: =AVERAGE(J2:J63) -> 1.538821 | K64: =AVERAGE(K2:K63) -> 1.5350645 | L64: =AVERAGE(L2:L63) -> 1.5384839 | P64: =AVERAGE(P2:P63) -> 2.3286935 | Q64: =AVERAGE(Q2:Q63) -> 2.2266935 | R64: =AVERAGE(R2:R63) -> 2.0861935 | S64: =AVERAGE(S2:S63) -> 2.0621774 | T64: =AVERAGE(T2:T63) -> 1.8033226 | V64: =AVERAGE(V2:V63) -> 1.6230968 | W64: =AVERAGE(W2:W63) -> 1.6256129 | X64: =AVERAGE(X2:X63) -> 1.6237097 | Y64: =AVERAGE(Y2:Y63) -> 1.6637258
A69: ①
B70: (1)テスト回路ごとに電力とLUT数を比較
B71: (実測) | D71: 62.5MHz | F71: 125MHz | K71: 62.5MHz | M71: 125MHz
D72: LUT | E72: POWER | F72: LUT | G72: POWER | K72: LUT | L72: POWER | M72: LUT | N72: POWER
C73: 300N4M | D73: =TEG_Syncronous_Pipeline_回路規模!$I$3 -> 30884 | E73: =C64 -> 1.885 | F73: =TEG_Syncronous_Pipeline_回路規模!$I$3 -> 30884 | G73: =P64 -> 2.3286935 | J73: 4M-3M | K73: =D73-D74 -> 7988 | L73: =$E$73-$E$74 -> 0.035725806 | M73: =F73-F74 -> 7988 | N73: =$G$73-$G$74 -> 0.102
C74: 300N3M | D74: =TEG_Syncronous_Pipeline_回路規模!$I$4 -> 22896 | E74: =D64 -> 1.8492742 | F74: =TEG_Syncronous_Pipeline_回路規模!$I$4 -> 22896 | G74: =Q64 -> 2.2266935 | J74: 4M-2M | K74: =D73-D75 -> 15556 | L74: =$E$73-$E$75 -> 0.11795161 | M74: =F73-F75 -> 15556 | N74: =$G$73-$G$75 -> 0.2425
C75: 300N2M | D75: =TEG_Syncronous_Pipeline_回路規模!$I$5 -> 15328 | E75: =E64 -> 1.7670484 | F75: =TEG_Syncronous_Pipeline_回路規模!$I$5 -> 15328 | G75: =R64 -> 2.0861935 | J75: 4M-1M | K75: =D73-D76 -> 23054 | L75: =$E$73-$E$76 -> 0.18108065 | M75: =F73-F76 -> 23054 | N75: =$G$73-$G$76 -> 0.26651613
C76: 300N1M | D76: =TEG_Syncronous_Pipeline_回路規模!$I$6 -> 7830 | E76: =F64 -> 1.7039194 | F76: =TEG_Syncronous_Pipeline_回路規模!$I$6 -> 7830 | G76: =S64 -> 2.0621774 | J76: 3M-2M | K76: =D74-D75 -> 7568 | L76: =$E$74-$E$75 -> 0.082225806 | M76: =F74-F75 -> 7568 | N76: =$G$74-$G$75 -> 0.1405
J77: 3M-1M | K77: =D74-D76 -> 15066 | L77: =$E$74-$E$76 -> 0.14535484 | M77: =F74-F76 -> 15066 | N77: =$G$74-$G$76 -> 0.16451613
J78: 2M-1M | K78: =D75-D76 -> 7498 | L78: =$E$75-$E$76 -> 0.063129032 | M78: =F75-F76 -> 7498 | N78: =$G$75-$G$76 -> 0.024016129
A84: ②
B85: (1)テスト回路ごとに電力とLUT数を比較 (動作時ー停止時)
B86: (実測) | D86: 62.5MHz | F86: 125MHz | J86: 62.5MHz | L86: 125MHz
D87: LUT | E87: POWER | F87: LUT | G87: POWER | J87: LUT | K87: POWER | L87: LUT | M87: POWER
C88: 300N4M | D88: =TEG_Syncronous_Pipeline_回路規模!$I$3 -> 30884 | E88: =C64-I64 -> 0.3501129 | F88: =TEG_Syncronous_Pipeline_回路規模!$I$3 -> 30884 | G88: =P64-V64 -> 0.70559677 | I88: 4M-3M | J88: =$D$88-$D$89 -> 7988 | K88: =$E$88-$E$89 -> 0.039659677 | L88: =F88-F89 -> 7988 | M88: =$G$88-$G$89 -> 0.10451613
C89: 300N3M | D89: =TEG_Syncronous_Pipeline_回路規模!$I$4 -> 22896 | E89: =D64-J64 -> 0.31045323 | F89: =TEG_Syncronous_Pipeline_回路規模!$I$4 -> 22896 | G89: =Q64-W64 -> 0.60108065 | I89: 4M-2M | J89: =$D$88-$D$90 -> 15556 | K89: =$E$88-$E$90 -> 0.11812903 | L89: =F88-F90 -> 15556 | M89: =$G$88-$G$90 -> 0.2431129
C90: 300N2M | D90: =TEG_Syncronous_Pipeline_回路規模!$I$5 -> 15328 | E90: =E64-K64 -> 0.23198387 | F90: =TEG_Syncronous_Pipeline_回路規模!$I$5 -> 15328 | G90: =R64-X64 -> 0.46248387 | I90: 4M-1M | J90: =$D$88-$D$91 -> 23054 | K90: =$E$88-$E$91 -> 0.18467742 | L90: =F88-F91 -> 23054 | M90: =$G$88-$G$91 -> 0.30714516
C91: 300N1M | D91: =TEG_Syncronous_Pipeline_回路規模!$I$6 -> 7830 | E91: =F64-L64 -> 0.16543548 | F91: =TEG_Syncronous_Pipeline_回路規模!$I$6 -> 7830 | G91: =S64-Y64 -> 0.39845161 | I91: 3M-2M | J91: =$D$89-$D$90 -> 7568 | K91: =$E$89-$E$90 -> 0.078469355 | L91: =F89-F90 -> 7568 | M91: =$G$89-$G$90 -> 0.13859677
I92: 3M-1M | J92: =$D$89-$D$91 -> 15066 | K92: =$E$89-$E$91 -> 0.14501774 | L92: =F89-F91 -> 15066 | M92: =$G$89-$G$91 -> 0.20262903
I93: 2M-1M | J93: =$D$90-$D$91 -> 7498 | K93: =$E$90-$E$91 -> 0.066548387 | L93: =F90-F91 -> 7498 | M93: =$G$90-$G$91 -> 0.064032258
A100: ③ | B100: 方法１、２、推定の比較 | P100: 全て比較
B101: 推定電力 | C101: 62.5MHz | D101: 125MHz | E101: 62.5MHz | F101: 125MHz | R101: 62.5MHz | V101: 125MHz | AH101: 62.5MHz | AK101: 125MHz
B102: 300N5M | E102: 0.853 | F102: 1.262 | J102: 62.5MHz | L102: 125MHz | Q102: LUT | R102: Plan.1 Power | S102: Plan.2 Power | T102: Estimation | U102: LUT | V102: Plan.1 Power | W102: Plan.2 Power | X102: Estimation | AG102: LUT | AH102: Plan.1 Power | AI102: Plan.2 Power | AJ102: Estimation | AK102: Plan.1 Power | AL102: Plan.2 Power | AM102: Estimation
B103: 300N4M | C103: 0.479 | D103: 0.887 | E103: 0.581 | F103: 1.099 | J103: LUT | K103: POWER | L103: LUT | M103: POWER | P103: 4M-3M | Q103: =$D$88-$D$89 -> 7988 | R103: =$E$73-$E$74 -> 0.035725806 | S103: =$E$88-$E$89 -> 0.039659677 | T103: =$C$103-$C$104 -> 0.023 | U103: =$D$88-$D$89 -> 7988 | V103: =$G$73-$G$74 -> 0.102 | W103: =$G$88-$G$89 -> 0.10451613 | X103: =$D$103-$D$104 -> 0.075 | AG103: =$D$88-$D$89 -> 7988 | AH103: =$E$73-$E$74 -> 0.035725806 | AI103: =$E$88-$E$89 -> 0.039659677 | AJ103: =$C$103-$C$104 -> 0.023 | AK103: =$G$73-$G$74 -> 0.102 | AL103: =$G$88-$G$89 -> 0.10451613 | AM103: =$D$103-$D$104 -> 0.075
B104: 300N3M | C104: 0.456 | D104: 0.812 | E104: 0.533 | F104: 0.972 | I104: 4M-3M | J104: =$D$88-$D$89 -> 7988 | K104: =$C$103-$C$104 -> 0.023 | L104: =$D$88-$D$89 -> 7988 | M104: =$D$103-$D$104 -> 0.075 | P104: 4M-2M | Q104: =$D$88-$D$90 -> 15556 | R104: =$E$73-$E$75 -> 0.11795161 | S104: =$E$88-$E$90 -> 0.11812903 | T104: =$C$103-$C$105 -> 0.106 | U104: =$D$88-$D$90 -> 15556 | V104: =$G$73-$G$75 -> 0.2425 | W104: =$G$88-$G$90 -> 0.2431129 | X104: =$D$103-$D$105 -> 0.221 | AG104: =$D$88-$D$90 -> 15556 | AH104: =$E$73-$E$75 -> 0.11795161 | AI104: =$E$88-$E$90 -> 0.11812903 | AJ104: =$C$103-$C$105 -> 0.106 | AK104: =$G$73-$G$75 -> 0.2425 | AL104: =$G$88-$G$90 -> 0.2431129 | AM104: =$D$103-$D$105 -> 0.221
...

Sheet Sync回路_検証用データ群
A1: 400N3M | D1: 400N2M | G1: 200N8M | J1: 200N4M | M1: 50N16M | P1: 50N8M
B2: 62.5MHz | C2: 125MHz | E2: 62.5MHz | F2: 125MHz | H2: 62.5MHz | I2: 125MHz | K2: 62.5MHz | L2: 125MHz | N2: 62.5MHz | O2: 125MHz | Q2: 62.5MHz | R2: 125MHz
A3: 0 | B3: 1.921 | C3: 2.368 | D3: 0 | E3: 1.859 | F3: 2.256 | G3: 0 | H3: 2.207 | I3: Timing違反 | J3: 0 | K3: 2.021 | L3: 2.526 | M3: 0 | N3: 1.683 | O3: Timing違反 | P3: 0 | Q3: 1.618 | R3: Timing違反
A4: 0 | B4: 1.921 | C4: 2.392 | D4: 0 | E4: 1.866 | F4: 2.25 | G4: 0 | H4: 2.211 | J4: 0 | K4: 2.021 | L4: 2.526 | M4: 0 | N4: 1.683 | P4: 0 | Q4: 1.608
A5: 1 | B5: 1.928 | C5: 2.382 | D5: 1 | E5: 1.869 | F5: 2.252 | G5: 1 | H5: 2.211 | J5: 1 | K5: 2.037 | L5: 2.536 | M5: 1 | N5: 1.689 | P5: 1 | Q5: 1.605
A6: 1 | B6: 1.921 | C6: 2.368 | D6: 1 | E6: 1.855 | F6: 2.252 | G6: 1 | H6: 2.197 | J6: 1 | K6: 2.012 | L6: 2.536 | M6: 1 | N6: 1.689 | P6: 1 | Q6: 1.616
A7: 2 | B7: 1.931 | C7: 2.378 | D7: 2 | E7: 1.855 | F7: 2.266 | G7: 2 | H7: 2.211 | J7: 2 | K7: 2.012 | L7: 2.526 | M7: 2 | N7: 1.689 | P7: 2 | Q7: 1.616
A8: 2 | B8: 1.921 | C8: 2.378 | D8: 2 | E8: 1.866 | F8: 2.266 | G8: 2 | H8: 2.211 | J8: 2 | K8: 2.021 | L8: 2.526 | M8: 2 | N8: 1.692 | P8: 2 | Q8: 1.608
A9: 3 | B9: 1.928 | C9: 2.378 | D9: 3 | E9: 1.859 | F9: 2.246 | G9: 3 | H9: 2.207 | J9: 3 | K9: 2.016 | L9: 2.536 | M9: 3 | N9: 1.689 | P9: 3 | Q9: 1.616
A10: 3 | B10: 1.928 | C10: 2.368 | D10: 3 | E10: 1.859 | F10: 2.246 | G10: 3 | H10: 2.207 | J10: 3 | K10: 2.021 | L10: 2.536 | M10: 3 | N10: 1.68 | P10: 3 | Q10: 1.608
A11: 4 | B11: 1.921 | C11: 2.382 | D11: 4 | E11: 1.859 | F11: 2.252 | G11: 4 | H11: 2.207 | J11: 4 | K11: 2.017 | L11: 2.521 | M11: 4 | N11: 1.689 | P11: 4 | Q11: 1.616
A12: 4 | B12: 1.921 | C12: 2.382 | D12: 4 | E12: 1.855 | F12: 2.242 | G12: 4 | H12: 2.211 | J12: 4 | K12: 2.017 | L12: 2.536 | M12: 4 | N12: 1.683 | P12: 4 | Q12: 1.618
A13: 5 | B13: 1.921 | C13: 2.378 | D13: 5 | E13: 1.859 | F13: 2.242 | G13: 5 | H13: 2.2 | J13: 5 | K13: 2.016 | L13: 2.536 | M13: 5 | N13: 1.689 | P13: 5 | Q13: 1.608
A14: 5 | B14: 1.921 | C14: 2.382 | D14: 5 | E14: 1.859 | F14: 2.246 | G14: 5 | H14: 2.211 | J14: 5 | K14: 2.021 | L14: 2.536 | M14: 5 | N14: 1.683 | P14: 5 | Q14: 1.616
A15: 6 | B15: 1.921 | C15: 2.382 | D15: 6 | E15: 1.869 | F15: 2.256 | G15: 6 | H15: 2.221 | J15: 6 | K15: 2.021 | L15: 2.526 | M15: 6 | N15: 1.692 | P15: 6 | Q15: 1.629
... A64: 30 | B64: 1.921 | C64: 2.372 | D64: 30 | E64: 1.849 | F64: 2.256 | G64: 30 | H64: 2.211 | J64: 30 | K64: 2.002 | L64: 2.536 | M64: 30 | N64: 1.689 | P64: 30 | Q64: 1.618
B65: =AVERAGE(B3:B64) -> 1.919371 | C65: =AVERAGE(C3:C64) -> 2.3798387 | E65: =AVERAGE(E3:E64) -> 1.8591452 | F65: =AVERAGE(F3:F64) -> 2.2529516 | H65: =AVERAGE(H3:H64) -> 2.2084516 | K65: =AVERAGE(K3:K64) -> 2.0189194 | L65: =AVERAGE(L3:L64) -> 2.5301129 | N65: =AVERAGE(N3:N64) -> 1.6870968 | Q65: =AVERAGE(Q3:Q64) -> 1.6117742
G68: 再調査
G69: 200N8M | J69: 200N4M
H70: 62.5MHz | I70: 125MHz | K70: 62.5MHz | L70: 125MHz
G71: 0 | H71: 1.992 | J71: 0 | K71: 1.808 | L71: 2.125
G72: 0 | H72: 1.982 | J72: 0 | K72: 1.795 | L72: 2.125
G73: 1 | H73: 1.982 | J73: 1 | K73: 1.795 | L73: 2.105
G74: 1 | H74: 1.992 | J74: 1 | K74: 1.793 | L74: 2.118
G75: 2 | H75: 1.992 | J75: 2 | K75: 1.798 | L75: 2.108
G76: 2 | H76: 1.992 | J76: 2 | K76: 1.795 | L76: 2.108
G77: 3 | H77: 1.982 | J77: 3 | K77: 1.79 | L77: 2.115
G78: 3 | H78: 1.978 | J78: 3 | K78: 1.79 | L78: 2.105
G79: 4 | H79: 2.002 | J79: 4 | K79: 1.795 | L79: 2.101
G80: 4 | H80: 1.992 | J80: 4 | K80: 1.798 | L80: 2.108
G81: 5 | H81: 1.992 | J81: 5 | K81: 1.786 | L81: 2.115
G82: 5 | H82: 1.992 | J82: 5 | K82: 1.793 | L82: 2.118
... G132: 30 | H132: 1.992 | J132: 30 | K132: 1.798 | L132: 2.115
H133: =AVERAGE(H71:H132) -> 1.9903871 | K133: =AVERAGE(K71:K132) -> 1.7957742 | L133: =AVERAGE(L71:L132) -> 2.1136129

Sheet Sync回路回帰分析
D3: 100N16M~1M | H3: 300N4M~1M62.5MHz | J3: 300N4M~1M125MHz
D4: SynthesisLUT | E4: POWER | H4: SynthesisLUT | I4: POWER | J4: SynthesisLUT | K4: POWER
C5: 16M-12M | D5: =TEG_Syncronous_Pipeline_回路規模!$C$2-TEG_Syncronous_Pipeline_回路規模!$C$3 -> 3775 | E5: =電力データ_0610以降_100N!$C$130-電力データ_0610以降_100N!$C$131 -> 0.076 | G5: 4M-3M | H5: =H13-H14 -> 7988 | I5: =電力データ0610以降_300N!E134 -> 0.039659677 | J5: =H13-H14 -> 7988 | K5: =電力データ0610以降_300N!I134 -> 0.10451613
C6: 16M-8M | D6: =TEG_Syncronous_Pipeline_回路規模!$C$2-TEG_Syncronous_Pipeline_回路規模!$C$4 -> 8042 | E6: =電力データ_0610以降_100N!$C$130-電力データ_0610以降_100N!$C$132 -> 0.174 | G6: 4M-2M | H6: =H13-H15 -> 15556 | I6: =電力データ0610以降_300N!E135 -> 0.11812903 | J6: =H13-H15 -> 15556 | K6: =電力データ0610以降_300N!I135 -> 0.2431129
C7: 16M-4M | D7: =TEG_Syncronous_Pipeline_回路規模!$C$2-TEG_Syncronous_Pipeline_回路規模!$C$5 -> 17660 | E7: =電力データ_0610以降_100N!$C$130-電力データ_0610以降_100N!$C$133 -> 0.272 | G7: 4M-1M | H7: =H13-H16 -> 23054 | I7: =電力データ0610以降_300N!E136 -> 0.18467742 | J7: =H13-H16 -> 23054 | K7: =電力データ0610以降_300N!I136 -> 0.30714516
C8: 16M-2M | D8: =TEG_Syncronous_Pipeline_回路規模!$C$2-TEG_Syncronous_Pipeline_回路規模!$C$6 -> 23794 | E8: =電力データ_0610以降_100N!$C$130-電力データ_0610以降_100N!$C$134 -> 0.322 | G8: 3M-2M | H8: =H14-H9 -> 15066 | I8: =電力データ0610以降_300N!E137 -> 0.078469355 | J8: =H14-H15 -> 7568 | K8: =電力データ0610以降_300N!I137 -> 0.13859677
C9: 16M-1M | D9: =TEG_Syncronous_Pipeline_回路規模!$C$2-TEG_Syncronous_Pipeline_回路規模!$C$7 -> 26971 | E9: =電力データ_0610以降_100N!$C$130-電力データ_0610以降_100N!$C$135 -> 0.345 | G9: 3M-1M | H9: =H16 -> 7830 | I9: =電力データ0610以降_300N!E138 -> 0.14501774 | J9: =H14-H16 -> 15066 | K9: =電力データ0610以降_300N!I138 -> 0.20262903
C10: 12M -8M | D10: =TEG_Syncronous_Pipeline_回路規模!$C$3-TEG_Syncronous_Pipeline_回路規模!$C$4 -> 4267 | E10: =電力データ_0610以降_100N!$C$131-電力データ_0610以降_100N!$C$132 -> 0.098 | G10: 2M-1M | H10: =H15-H16 -> 7498 | I10: =電力データ0610以降_300N!E139 -> 0.066548387 | J10: =H15-H16 -> 7498 | K10: =電力データ0610以降_300N!I139 -> 0.064032258
C11: 12M-4M | D11: =TEG_Syncronous_Pipeline_回路規模!$C$3-TEG_Syncronous_Pipeline_回路規模!$C$5 -> 13885 | E11: =電力データ_0610以降_100N!$C$131-電力データ_0610以降_100N!$C$133 -> 0.196
C12: 12M-2M | D12: =TEG_Syncronous_Pipeline_回路規模!$C$3-TEG_Syncronous_Pipeline_回路規模!$C$6 -> 20019 | E12: =電力データ_0610以降_100N!$C$131-電力データ_0610以降_100N!$C$134 -> 0.246
C13: 12M-1M | D13: =TEG_Syncronous_Pipeline_回路規模!$C$3-TEG_Syncronous_Pipeline_回路規模!$C$7 -> 23196 | E13: =電力データ_0610以降_100N!$C$131-電力データ_0610以降_100N!$C$135 -> 0.269 | H13: =TEG_Syncronous_Pipeline_回路規模!$I$3 -> 30884
C14: 8M-4M | D14: =TEG_Syncronous_Pipeline_回路規模!$C$4-TEG_Syncronous_Pipeline_回路規模!$C$5 -> 9618 | E14: =電力データ_0610以降_100N!$C$132-電力データ_0610以降_100N!$C$133 -> 0.098 | H14: =TEG_Syncronous_Pipeline_回路規模!$I$4 -> 22896
C15: 8M-2M | D15: =TEG_Syncronous_Pipeline_回路規模!$C$4-TEG_Syncronous_Pipeline_回路規模!$C$6 -> 15752 | E15: =電力データ_0610以降_100N!$C$132-電力データ_0610以降_100N!$C$134 -> 0.148 | H15: =TEG_Syncronous_Pipeline_回路規模!$I$5 -> 15328
C16: 8M-1M | D16: =TEG_Syncronous_Pipeline_回路規模!$C$4-TEG_Syncronous_Pipeline_回路規模!$C$7 -> 18929 | E16: =電力データ_0610以降_100N!$C$132-電力データ_0610以降_100N!$C$135 -> 0.171 | H16: =TEG_Syncronous_Pipeline_回路規模!$I$6 -> 7830
C17: 4M-2M | D17: =TEG_Syncronous_Pipeline_回路規模!$C$5-TEG_Syncronous_Pipeline_回路規模!$C$6 -> 6134 | E17: =電力データ_0610以降_100N!$C$133-電力データ_0610以降_100N!$C$134 -> 0.05
C18: 4M-1M | D18: =TEG_Syncronous_Pipeline_回路規模!$C$5-TEG_Syncronous_Pipeline_回路規模!$C$7 -> 9311 | E18: =電力データ_0610以降_100N!$C$133-電力データ_0610以降_100N!$C$135 -> 0.073
C19: 2M-1M | D19: =TEG_Syncronous_Pipeline_回路規模!$C$6-TEG_Syncronous_Pipeline_回路規模!$C$7 -> 3177 | E19: =電力データ_0610以降_100N!$C$134-電力データ_0610以降_100N!$C$135 -> 0.023
C25: テスト回路名 | D25: NOT段数 | E25: レジスタ数 | F25: imp LUT | G25: syn LUT | H25: 100N62.5MHz電力
C26: 62.5MHz100N16M | D26: 16 | E26: 3351 | F26: =TEG_Syncronous_Pipeline_回路規模!$C$2 -> 30226 | G26: =TEG_Syncronous_Pipeline_回路規模!D11 -> 51293 | H26: =電力データ_0610以降_100N!$F$224 -> 1.8938226
C27: 62.5MHz100N12M | D27: 12 | E27: 3351 | F27: =TEG_Syncronous_Pipeline_回路規模!$C$3 -> 26451 | G27: =TEG_Syncronous_Pipeline_回路規模!D12 -> 38497 | H27: =電力データ_0610以降_100N!$F$225 -> 1.8137097
C28: 62.5MHz100N8M | D28: 8 | E28: 3351 | F28: =TEG_Syncronous_Pipeline_回路規模!$C$4 -> 22184 | G28: =TEG_Syncronous_Pipeline_回路規模!D13 -> 25697 | H28: =電力データ_0610以降_100N!$F$226 -> 1.7232742
C29: 62.5MHz100N4M | D29: 4 | E29: 3351 | F29: =TEG_Syncronous_Pipeline_回路規模!$C$5 -> 12566 | G29: =TEG_Syncronous_Pipeline_回路規模!D14 -> 12897 | H29: =電力データ_0610以降_100N!$F$227 -> 1.6362419
C30: 62.5MHz100N2M | D30: 2 | E30: 3351 | F30: =TEG_Syncronous_Pipeline_回路規模!$C$6 -> 6432 | G30: =TEG_Syncronous_Pipeline_回路規模!D15 -> 6497 | H30: =電力データ_0610以降_100N!$F$228 -> 1.5922097
C31: 62.5MHz100N1M | D31: 1 | E31: 3351 | F31: =TEG_Syncronous_Pipeline_回路規模!$C$7 -> 3255 | G31: =TEG_Syncronous_Pipeline_回路規模!D16 -> 3297 | H31: =電力データ_0610以降_100N!$F$229 -> 1.5545
C32: 62.5MHz100N0M | D32: 0 | E32: 3351 | F32: =TEG_Syncronous_Pipeline_回路規模!$C$8 -> 96 | H32: =電力データ_0610以降_100N!$I$65 -> 1.5473065
C33: テスト回路名 | D33: NOT段数 | E33: レジスタ数 | F33: imp LUT | G33: syn LUT | H33: 300N62.5MHz電力
C34: 62.5MHz300N4M | D34: 4 | E34: =電力データ0610以降_300N!$D$177 -> 9786 | F34: =TEG_Syncronous_Pipeline_回路規模!$I$3 -> 30884 | G34: =TEG_Syncronous_Pipeline_回路規模!K3 -> 38497 | H34: =電力データ0610以降_300N!$F$177 -> 1.885
C35: 62.5MHz300N3M | D35: 3 | E35: =電力データ0610以降_300N!$D$178 -> 9786 | F35: =TEG_Syncronous_Pipeline_回路規模!$I$4 -> 22896 | G35: =TEG_Syncronous_Pipeline_回路規模!K4 -> 28897 | H35: =電力データ0610以降_300N!$F$178 -> 1.8492742
C36: 62.5MHz300N2M | D36: 2 | E36: =電力データ0610以降_300N!$D$179 -> 9786 | F36: =TEG_Syncronous_Pipeline_回路規模!$I$5 -> 15328 | G36: =TEG_Syncronous_Pipeline_回路規模!K5 -> 19297 | H36: =電力データ0610以降_300N!$F$179 -> 1.7670484
C37: 62.5MHz300N1M | D37: 1 | E37: =電力データ0610以降_300N!$D$180 -> 9786 | F37: =TEG_Syncronous_Pipeline_回路規模!$I$6 -> 7830 | G37: =TEG_Syncronous_Pipeline_回路規模!K6 -> 9697 | H37: =電力データ0610以降_300N!$F$180 -> 1.7039194
C38: 62.5MHz300N0M | D38: 0 | E38: 9786 | F38: =TEG_Syncronous_Pipeline_回路規模!$I$7 -> 96 | H38: =電力データ0610以降_300N!$G$64 -> 1.634371
H39: 300N125MHz電力
C40: 125MHz300N4M | D40: 4 | E40: =電力データ0610以降_300N!$D$177 -> 9786 | F40: =TEG_Syncronous_Pipeline_回路規模!$I$3 -> 30884 | G40: =TEG_Syncronous_Pipeline_回路規模!K3 -> 38497 | H40: =電力データ0610以降_300N!$G$177 -> 2.3286935
C41: 125MHz300N3M | D41: 3 | E41: =電力データ0610以降_300N!$D$178 -> 9786 | F41: =TEG_Syncronous_Pipeline_回路規模!$I$4 -> 22896 | G41: =TEG_Syncronous_Pipeline_回路規模!K4 -> 28897 | H41: =電力データ0610以降_300N!$G$178 -> 2.2266935
C42: 125MHz300N2M | D42: 2 | E42: =電力データ0610以降_300N!$D$179 -> 9786 | F42: =TEG_Syncronous_Pipeline_回路規模!$I$5 -> 15328 | G42: =TEG_Syncronous_Pipeline_回路規模!K5 -> 19297 | H42: =電力データ0610以降_300N!$G$179 -> 2.0861935
C43: 125MHz300N1M | D43: 1 | E43: =電力データ0610以降_300N!$D$180 -> 9786 | F43: =TEG_Syncronous_Pipeline_回路規模!$I$6 -> 7830 | G43: =TEG_Syncronous_Pipeline_回路規模!K6 -> 9697 | H43: =電力データ0610以降_300N!$G$180 -> 2.0621774
A44: 分析用 | C44: 125MHz300N0M | D44: 0 | E44: 9786 | F44: =TEG_Syncronous_Pipeline_回路規模!$I$7 -> 96 | H44: =電力データ0610以降_300N!$T$64 -> 1.8033226 | J44: 得た係数をもとに推定した電力 | Y44: ① | Z44: レジスタ数、ImpLUT数を変数に | AN44: ①ー２ | BR44: 考察：回路の停止時電力に差がある（恐らくレジスタ数、動作周波数が影響）ので、動作時電力にこれを加味するべきか否か
A45: サンプル名 | B45: サンプル | C45: Y（電力[W]） | D45: X1（周波数[MHz]） | E45: X2 （N：ステージ数） | F45: X3（M：Not段数） | K45: Y（電力[W]） | L45: X1（周波数[MHz]） | M45: X2 （N：ステージ数） | N45: X3（M：Not段数） | O45: 切片 | Y45: 分析用 | AH45: Y（電力[W]） | AI45: X1（周波数[MHz]） | AJ45: X2 （レジスタ数） | AK45: X3（LUT数） | AL45: 切片 | AN45: 検証用 | AO45: 実測値 | AP45: Y（電力[W]） | AQ45: X1（周波数[MHz]） | AR45: X2 （レジスタ数） | AS45: X3（LUT数） | AT45: 切片 | BL45: 停止時電力を引く→ボードの電力を除いてみrう | BR45: 完全に回路が静止しているわけではなく、Inputデータの更新が止まっているだけ→CLKは常に動作している→CLKが「停止時電力」の差に現れている
A46: 100N16M | B46: 0 | C46: =電力データ_0610以降_100N!$F$224 -> 1.8938226 | D46: 62.5 | E46: 100 | F46: 16 | L46: 0.0053358968 | M46: 0.0010194623 | N46: 0.028029436 | O46: 1.0725315 | Y46: サンプル名 | Z46: サンプル | AA46: Y（電力[W]） | AB46: X1（周波数[MHz]） | AC46: X2-1Reginum | AD46: X3-1 Imp LUTnum | AE46: 予備 | AI46: 0.0053358968 | AJ46: 1.1918127e-05 | AK46: 1.1682162e-05 | AL46: =Z82 -> 1.1378135 | AP46: 推定値 | AQ46: 0.0053358968 | AR46: 1.1918127e-05 | AS46: 1.1682162e-05 | AT46: 1.1378135 | BR46: 回路停止時電力ではないのでこの手法はいまいち？岡村のように、停止時電力を測る用の回路を作るなどの方法が必要
A47: 100N12M | B47: 1 | C47: =電力データ_0610以降_100N!$F$225 -> 1.8137097 | D47: 62.5 | E47: 100 | F47: 12 | J47: 100N16M | K47: =L47*$L$46+M47*$M$46+N47*$N$46+$O$46 -> 1.9564422 | L47: 62.5 | M47: 100 | N47: 16 | Y47: 100N16M | Z47: 0 | AA47: =電力データ_0610以降_100N!$F$224 -> 1.8938226 | AB47: 62.5 | AC47: 3351 | AD47: =TEG_Syncronous_Pipeline_回路規模!$C$2 -> 30226 | AG47: 100N16M | AH47: =AI47*$AI$46+AJ47*$AJ$46+AK47*$AK$46+$AL$46 -> 1.8643497 | AI47: 62.5 | AJ47: 3351 | AK47: =TEG_Syncronous_Pipeline_回路規模!$C$2 -> 30226 | AN47: 62.5MHz400N3M | AO47: =Sync回路_検証用データ群!B65 -> 1.919371 | AP47: =AQ47*$AQ$46+AR47*$AR$46+AS47*$AS$46+$AT$46 -> 1.9617511 | AQ47: 62.5 | AR47: =TEG_Syncronous_Pipeline_回路規模!E19 -> 12986 | AS47: =TEG_Syncronous_Pipeline_回路規模!B19 -> 28734 | BL47: サンプル名 | BM47: サンプル | BN47: 動作時電力[W]） | BO47: 停止時電力 | BP47: 実装回路動作時電力100N62.5MHz | BQ47: X1（周波数[MHz]） | BR47: X2-1Reginum | BS47: X3-1 Imp LUTnum | BT47: 予備 | BW47: 概要
...

Sheet 電力データ_Async回路
A1: 非同期テスト回路電力データ
A3: テストパターン
A4: Async | B4: 20MHz | C4: 100N | D4: 12N~1N | E4: 12N | F4: 10N | G4: 8N | H4: 6N | I4: 4N | J4: 2N | K4: 0N | L4: `
B5: 50MHz | C5: 100N | D5: 12N~1N
B6: 20MHz | C6: 50N | D6: 12N~1N
B7: 50MHz | C7: 50N | D7: 12N~1N
A12: Asyncではシミュレーションと実機で、動作速度が異なる可能性がある
A13: Sendが100回立ち下がる回数をシミュレーションと実機で確認する | P13: imp LUT | Q13: impReg | R13: スライス
A14: 10進数表記 | E14: 12N | F14: 10N | G14: 8N | H14: 6N | I14: 4N | J14: 2N | K14: 0N | M14: 20MHｚ | N14: 100N | O14: 12N | P14: 31235 | Q14: 3334 | R14: 8380
A15: Async | B15: 20MHz | C15: 100N | D15: 実機(0x) | E15: 271 | F15: 26d | G15: 270 | H15: 270 | I15: 270 | J15: 270 | K15: 26e | O15: 10N | P15: 28508 | Q15: 3334 | R15: 7956
D16: 10進 | E16: =HEX2DEC(E15) -> 625 | F16: =HEX2DEC(F15) -> 621 | G16: =HEX2DEC(G15) -> 624 | H16: =HEX2DEC(H15) -> 624 | I16: =HEX2DEC(I15) -> 624 | J16: =HEX2DEC(J15) -> 624 | K16: =HEX2DEC(K15) -> 622 | O16: 8N | P16: 25505 | Q16: 3334 | R16: 7770
D17: Time(ns) | E17: =E16*8 -> 5000 | F17: =F16*8 -> 4968 | G17: =G16*8 -> 4992 | H17: =H16*8 -> 4992 | I17: =I16*8 -> 4992 | J17: =J16*8 -> 4992 | K17: =K16*8 -> 4976 | O17: 6N | P17: 21573 | Q17: 3334 | R17: 7365
D18: Simulation10進 | E18: 925 | F18: 924 | G18: 925 | H18: 931 | I18: 931 | J18: 931 | K18: 873 | O18: 4N | P18: 17266 | Q18: 3334 | R18: 6807
D19: Time(ns) | E19: =E18*8 -> 7400 | F19: =F18*8 -> 7392 | G19: =G18*8 -> 7400 | H19: =H18*8 -> 7448 | I19: =I18*8 -> 7448 | J19: =J18*8 -> 7448 | K19: =K18*8 -> 6984 | O19: 2N | P19: 12311 | Q19: 3334 | R19: 6174
D20: Siｍ上Tf | E20: 48.277ns | F20: 48.277ns | G20: 48.277ns | H20: 48.788ns | I20: 48.788ns | J20: 48.788ns | K20: 46.573ns | O20: 0N | P20: 6092 | Q20: 3334 | R20: 4777
C21: （タイミングの関係でCpが3回立ち上がるごとに1回休む） | I21: = | J21: =50*100*8/7 -> 5714.2857 | M21: 40MHz | N21: 100N | O21: 12N | P21: 27183 | Q21: 3334 | R21: 7150
C22: 1202検証 | E22: 12N | F22: 10N | G22: 8N | H22: 6N | I22: 4N | J22: 2N | K22: 0N | O22: 10N | P22: 25985 | Q22: 3334 | R22: 7125
D23: 実機(0x) | E23: 026F | F23: 026E | G23: 026C | H23: 026d | I23: 026d | J23: 26d | K23: 26d | O23: 8N | P23: 22190 | Q23: 3334 | R23: 7044
D24: 10進 | E24: =HEX2DEC(E23) -> 623 | F24: 624 | G24: =HEX2DEC(G23) -> 620 | H24: =HEX2DEC(H23) -> 621 | I24: =HEX2DEC(I23) -> 621 | J24: =HEX2DEC(J23) -> 621 | K24: =HEX2DEC(K23) -> 621 | O24: 6N | P24: 19771 | Q24: 3334 | R24: 6704
D25: Time(ns) | E25: =E24*8 -> 4984 | F25: =F24*8 -> 4992 | G25: =G24*8 -> 4960 | H25: =H24*8 -> 4968 | I25: =I24*8 -> 4968 | J25: =J24*8 -> 4968 | K25: =K24*8 -> 4968 | O25: 4N | P25: 15224 | Q25: 3334 | R25: 5983
D26: Simulation10進 | E26: 624 | F26: 624 | G26: 624 | H26: 621 | I26: 621 | J26: 621 | K26: 624 | O26: 2N | P26: 9003 | Q26: 3334 | R26: 4741
D27: Time(ns) | E27: =E26*8 -> 4992 | F27: =F26*8 -> 4992 | G27: =G26*8 -> 4992 | H27: =H26*8 -> 4968 | I27: =I26*8 -> 4968 | J27: =J26*8 -> 4968 | K27: =K26*8 -> 4992 | O27: 0N | P27: 2632 | Q27: 3334 | R27: 3825
D28: Siｍ上Tf | E28: 45.911 | F28: 45.911 | G28: 45.911 | H28: 45.911 | I28: 45.911 | J28: 45.911 | M28: 20MHｚ | N28: 50N | O28: 12N | P28: 15328 | Q28: 1734 | R28: 4099
D29: POWER | E29: 1.631~1.621 | F29: 1.616~1.605 | G29: 1.616~1.591 | H29: 1.610~1.578 | I29: 1.555~1.558 | J29: 1.555~1.535 | O29: 10N | P29: 14371 | Q29: 1734 | R29: 4030
D30: Time目安 | E30: =50*100 -> 5000 | O30: 8N | P30: 12839 | Q30: 1734 | R30: 3919
O31: 6N | P31: 10859 | Q31: 1734 | R31: 3716
A32: 40MHz | B32: 100N | D32: 12N | E32: 12N | F32: 10N | G32: 8N | H32: 6N | I32: 4N | J32: 2N | K32: 0N | O32: 4N | P32: 8722 | Q32: 1734 | R32: 3447
C33: 実機 | D33: 259 | O33: 2N | P33: 6236 | Q33: 1734 | R33: 3128
C34: 10進 | D34: =HEX2DEC(D33) -> 601 | O34: 0N | P34: 3120 | Q34: 1734 | R34: 2402
C35: Time(ns) | D35: =D34*8 -> 4808 | M35: 40MHz | N35: 50N | O35: 12N | P35: 13603 | Q35: 1734 | R35: 3599
C36: Simulation | D36: 416 | O36: 10N | P36: 13015 | Q36: 1734 | R36: 3589
C37: Time(ns) | D37: =D36*8 -> 3328 | O37: 8N | P37: 11469 | Q37: 1734 | R37: 3552
C38: Siｍ上Tf | D38: 23.8ns | O38: 6N | P38: 9879 | Q38: 1734 | R38: 3385
D39: 実機(0x) | E39: 136 | F39: 138 | G39: 138 | H39: 136 | I39: 137 | J39: 136 | K39: 136 | O39: 4N | P39: 7644 | Q39: 1734 | R39: 3037
D40: 10進 | E40: =HEX2DEC(E39) -> 310 | F40: =HEX2DEC(F39) -> 312 | G40: =HEX2DEC(G39) -> 312 | H40: =HEX2DEC(H39) -> 310 | I40: =HEX2DEC(I39) -> 311 | J40: =HEX2DEC(J39) -> 310 | K40: =HEX2DEC(K39) -> 310 | O40: 2N | P40: 4558 | Q40: 1734 | R40: 2416
D41: Time(ns) | E41: =E40*8 -> 2480 | F41: =F40*8 -> 2496 | G41: =G40*8 -> 2496 | H41: =H40*8 -> 2480 | I41: =I40*8 -> 2488 | J41: =J40*8 -> 2480 | K41: =K40*8 -> 2480 | O41: 0N | P41: 1382 | Q41: 1734 | R41: 1961
D42: Simulation10進 | E42: 311 | F42: 310 | G42: 310 | H42: 312 | I42: 310 | J42: 312 | K42: 311
D43: Time(ns) | E43: =E42*8 -> 2488 | F43: =F42*8 -> 2480 | G43: =G42*8 -> 2480 | H43: =H42*8 -> 2496 | I43: =I42*8 -> 2480 | J43: =J42*8 -> 2496 | K43: =K42*8 -> 2488
A48: Async | B48: 20MHz | C48: 50N | E48: 12N | F48: 10N | G48: 8N | H48: 6N | I48: 4N | J48: 2N | K48: 0N
D49: 実機(0x) | E49: 26F | F49: 026C | G49: 026d | H49: 26C | I49: 26C | J49: 26F | K49: 26E
...

Sheet Async回路回帰分析_グラフ出力
I2: ※LUTのうち45こが周辺回路なのでそれ以外がC素子とする
C3: POWER | D3: MHZ | E3: LUT | F3: Reg | H3: 特殊LUT※ | I3: C素子LUT数 | J3: =E10-45 -> 6047 | K3: これを元のLUTから引いた値
B4: 100N12M | C4: =電力データ_Async回路!B144 -> 1.6302581 | D4: 20 | E4: =電力データ_Async回路!$P$14 -> 31235 | F4: =電力データ_Async回路!$Q$14 -> 3334 | H4: =E4-$J$3 -> 25188
B5: 100N10M | C5: =電力データ_Async回路!C144 -> 1.6255323 | D5: 20 | E5: =電力データ_Async回路!$P$15 -> 28508 | F5: =電力データ_Async回路!$Q$15 -> 3334 | H5: =E5-$J$3 -> 22461
B6: 100N8M | C6: =電力データ_Async回路!D144 -> 1.6082903 | D6: 20 | E6: =電力データ_Async回路!$P$16 -> 25505 | F6: =電力データ_Async回路!$Q$16 -> 3334 | H6: =E6-$J$3 -> 19458
B7: 100N6M | C7: =電力データ_Async回路!E144 -> 1.5871452 | D7: 20 | E7: =電力データ_Async回路!$P$17 -> 21573 | F7: =電力データ_Async回路!$Q$17 -> 3334 | H7: =E7-$J$3 -> 15526
B8: 100N4M | C8: =電力データ_Async回路!F144 -> 1.5812581 | D8: 20 | E8: =電力データ_Async回路!$P$18 -> 17266 | F8: =電力データ_Async回路!$Q$18 -> 3334 | H8: =E8-$J$3 -> 11219
B9: 100N2M | C9: =電力データ_Async回路!G144 -> 1.567 | D9: 20 | E9: =電力データ_Async回路!$P$19 -> 12311 | F9: =電力データ_Async回路!$Q$19 -> 3334 | H9: =E9-$J$3 -> 6264
B10: 100N0M | C10: =電力データ_Async回路!H144 -> 1.5403387 | D10: 20 | E10: =電力データ_Async回路!$P$20 -> 6092 | F10: =電力データ_Async回路!$Q$20 -> 3334 | H10: =E10-$J$3 -> 45
B12: 同期 | C12: 非同期
B18: 概要
B20: 回帰統計
B21: 重相関 R | C21: 0.98136601
B22: 重決定 R2 | C22: 0.96307924
B23: 補正 R2 | C23: 0.95569509
B24: 標準誤差 | C24: 0.0068118049
B25: 観測数 | C25: 7
B27: 分散分析表
C28: 自由度 | D28: 変動 | E28: 分散 | F28: 観測された分散比 | G28: 有意 F
B29: 回帰 | C29: 1 | D29: 0.0060518176 | E29: 0.0060518176 | F29: 130.42517 | G29: 9.0130004e-05
B30: 残差 | C30: 5 | D30: 0.00023200343 | E30: 4.6400686e-05
B31: 合計 | C31: 6 | D31: 0.006283821
C33: 係数 | D33: 標準誤差 | E33: t | F33: P-値 | G33: 下限 95% | H33: 上限 95% | I33: 下限 95.0% | J33: 上限 95.0%
B34: 切片 | C34: 1.5166816 | D34: 0.0070311675 | E34: 215.70835 | F34: 4.0632078e-11 | G34: 1.4986074 | H34: 1.5347558 | I34: 1.4986074 | J34: 1.5347558
B35: X 値 1 | C35: 3.4817414e-06 | D35: 3.0487078e-07 | E35: 11.420384 | F35: 9.0130004e-05 | G35: 2.6980461e-06 | H35: 4.2654367e-06 | I35: 2.6980461e-06 | J35: 4.2654367e-06
C39: =Sync回路回帰分析!Z106/C35 -> 3.1719569
B41: 特殊LUT数を実LUTとしたときの係数
B42: 概要
B44: 回帰統計
B45: 重相関 R | C45: 0.98136601
B46: 重決定 R2 | C46: 0.96307924
B47: 補正 R2 | C47: 0.95569509
B48: 標準誤差 | C48: 0.0068118049
B49: 観測数 | C49: 7
B51: 分散分析表
C52: 自由度 | D52: 変動 | E52: 分散 | F52: 観測された分散比 | G52: 有意 F
B53: 回帰 | C53: 1 | D53: 0.0060518176 | E53: 0.0060518176 | F53: 130.42517 | G53: 9.0130004e-05
B54: 残差 | C54: 5 | D54: 0.00023200343 | E54: 4.6400686e-05
B55: 合計 | C55: 6 | D55: 0.006283821
C57: 係数 | D57: 標準誤差 | E57: t | F57: P-値 | G57: 下限 95% | H57: 上限 95% | I57: 下限 95.0% | J57: 上限 95.0%
...

Sheet DDP_Datasheet_16bit
A1: Data=16bit | P1: 動作周波数の導出
A2: Module name | E2: LUT | F2: SliceRegi | G2: Slice | H2: LUTasLogic | I2: BRAM | J2: DSPs | K2: BondedIOB | L2: BUFGCTRL | M2: PLLE2_ADV | P2: パケット送信周期 | R2: 5050 | S2: [ns]
A3: TOP | E3: 8077 | F3: 7008 | G3: 3397 | H3: 8077 | I3: 10.5 | J3: 4 | K3: 17 | L3: 2 | M3: 1 | P3: M~MM | Q3: ステージ通過パケット数 | R3: 74 | S3: [Packet]
B4: ddp0 | E4: 1987 | F4: 1722 | G4: 825 | H4: 1987 | I4: 2.5 | J4: 1 | K4: 0 | L4: 0 | M4: 0 | Q4: 動作周期 | R4: =R2/R3 -> 68.243243 | S4: [ns]
C5: M | E5: 28 | F5: 76 | G5: 25 | H5: 28 | I5: 0 | J5: 0 | K5: 0 | L5: 0 | M5: 0 | Q5: 動作周波数 | R5: 14.653 | S5: [MHz]
C6: MMCAM | E6: 745 | F6: 1326 | G6: 440 | H6: 745 | I6: 0 | J6: 0 | K6: 0 | L6: 0 | M6: 0 | P6: PS～MA | Q6: ステージ通過パケット数 | R6: 62 | S6: [Packet]
C7: MMRAM | E7: 95 | F7: 38 | G7: 35 | H7: 95 | I7: 1 | J7: 0 | K7: 0 | L7: 0 | M7: 0 | Q7: 動作周期 | R7: =R2/R6 -> 81.451613 | S7: [ns]
C8: PS | E8: 1 | F8: 52 | G8: 13 | H8: 1 | I8: 0.5 | J8: 0 | K8: 0 | L8: 0 | M8: 0 | Q8: 動作周波数 | R8: 12.27722 | S8: [MHz]
C9: FP | E9: 658 | F9: 62 | G9: 187 | H9: 658 | I9: 0 | J9: 1 | K9: 0 | L9: 0 | M9: 0 | P9: COPY～B | Q9: ステージ通過パケット数 | R9: 74 | S9: [Packet]
C10: MA | E10: 61 | F10: 41 | G10: 39 | H10: 61 | I10: 0.5 | J10: 0 | K10: 0 | L10: 0 | M10: 0 | Q10: 動作周期 | R10: =R2/R3 -> 68.243243 | S10: [ns]
C11: COPY | E11: 15 | F11: 40 | G11: 9 | H11: 15 | I11: 0 | J11: 0 | K11: 0 | L11: 0 | M11: 0 | Q11: 動作周波数 | R11: 14.653 | S11: [MHz]
C12: B | E12: 0 | F12: 38 | G12: 10 | H12: 0 | I12: 0.5 | J12: 0 | K12: 0 | L12: 0 | M12: 0
C13: C_output
C14: CC | E14: 382 | F14: 11 | G14: 109 | H14: 382 | I14: 0 | J14: 0 | K14: 0 | L14: 0 | M14: 0
D15: m | E15: 92 | F15: 0 | G15: 30 | H15: 92 | I15: 0 | J15: 0 | K15: 0 | L15: 0 | M15: 0
D16: mmcam | E16: 35 | F16: 0 | G16: 13 | H16: 35 | I16: 0 | J16: 0 | K16: 0 | L16: 0 | M16: 0
D17: mmram | E17: 35 | F17: 1 | G17: 13 | H17: 35 | I17: 0 | J17: 0 | K17: 0 | L17: 0 | M17: 0
D18: ps | E18: 35 | F18: 0 | G18: 12 | H18: 35 | I18: 0 | J18: 0 | K18: 0 | L18: 0 | M18: 0
D19: fp | E19: 28 | F19: 1 | G19: 9 | H19: 28 | I19: 0 | J19: 0 | K19: 0 | L19: 0 | M19: 0
D20: ma | E20: 44 | F20: 0 | G20: 17 | H20: 44 | I20: 0 | J20: 0 | K20: 0 | L20: 0 | M20: 0
D21: copy | E21: 60 | F21: 8 | G21: 22 | H21: 60 | I21: 0 | J21: 0 | K21: 0 | L21: 0 | M21: 0
D22: b | E22: 34 | F22: 1 | G22: 16 | H22: 34 | I22: 0 | J22: 0 | K22: 0 | L22: 0 | M22: 0
B26: ddp1 | E26: 1980 | F26: 1722 | G26: 825 | H26: 1987 | I26: 2.5 | J26: 1 | K26: 0 | L26: 0 | M26: 0
C27: M | E27: 28 | F27: 76 | G27: 19 | H27: 28 | I27: 0 | J27: 0 | K27: 0 | L27: 0 | M27: 0
C28: MMCAM | E28: 745 | F28: 1326 | G28: 435 | H28: 745 | I28: 0 | J28: 0 | K28: 0 | L28: 0 | M28: 0
C29: MMRAM | E29: 87 | F29: 38 | G29: 30 | H29: 87 | I29: 1 | J29: 0 | K29: 0 | L29: 0 | M29: 0
C30: PS | E30: 1 | F30: 52 | G30: 15 | H30: 1 | I30: 0.5 | J30: 0 | K30: 0 | L30: 0 | M30: 0
C31: FP | E31: 659 | F31: 62 | G31: 190 | H31: 659 | I31: 0 | J31: 1 | K31: 0 | L31: 0 | M31: 0
C32: MA | E32: 72 | F32: 41 | G32: 49 | H32: 72 | I32: 0.5 | J32: 0 | K32: 0 | L32: 0 | M32: 0
C33: COPY | E33: 16 | F33: 40 | G33: 10 | H33: 16 | I33: 0 | J33: 0 | K33: 0 | L33: 0 | M33: 0
C34: B | E34: 0 | F34: 38 | G34: 7 | H34: 0 | I34: 0.5 | J34: 0 | K34: 0 | L34: 0 | M34: 0
C35: C_output
C36: CC | E36: 371 | F36: 11 | G36: 107 | H36: 371 | I36: 0 | J36: 0 | K36: 0 | L36: 0 | M36: 0
D37: m | E37: 73 | F37: 0 | G37: 20 | H37: 73 | I37: 0 | J37: 0 | K37: 0 | L37: 0 | M37: 0
D38: mmcam | E38: 43 | F38: 0 | G38: 15 | H38: 43 | I38: 0 | J38: 0 | K38: 0 | L38: 0 | M38: 0
D39: mmram | E39: 34 | F39: 1 | G39: 13 | H39: 34 | I39: 0 | J39: 0 | K39: 0 | L39: 0 | M39: 0
D40: ps | E40: 34 | F40: 0 | G40: 13 | H40: 34 | I40: 0 | J40: 0 | K40: 0 | L40: 0 | M40: 0
D41: fp | E41: 31 | F41: 1 | G41: 10 | H41: 31 | I41: 0 | J41: 0 | K41: 0 | L41: 0 | M41: 0
D42: ma | E42: 41 | F42: 0 | G42: 15 | H42: 41 | I42: 0 | J42: 0 | K42: 0 | L42: 0 | M42: 0
D43: copy | E43: 69 | F43: 8 | G43: 22 | H43: 69 | I43: 0 | J43: 0 | K43: 0 | L43: 0 | M43: 0
...

Sheet DDP_Datasheet_32bit
A1: Data=32bit 回路規模と電力 | P1: 動作周波数の導出
A2: Module name | C2: Utilization | E2: LUT | F2: SliceRegi | G2: Slice | H2: LUTasLogic | I2: BRAM | J2: DSPs | K2: BondedIOB | L2: BUFGCTRL | M2: PLLE2_ADV | P2: パケット送信周期 | R2: 5050 | S2: [ns]
A3: TOP | E3: 11126 | F3: 7776 | G3: 4260 | H3: 11126 | I3: 12.5 | J3: 16 | K3: 17 | L3: 2 | M3: 1 | P3: M~MM | Q3: ステージ通過パケット数 | R3: 74 | S3: [Packet]
B4: ddp0 | E4: 2757 | F4: 1914 | G4: 1022 | H4: 2757 | I4: 3 | J4: 4 | K4: 0 | L4: 0 | M4: 0 | Q4: 動作周期 | R4: =R2/R3 -> 68.243243 | S4: [ns]
C5: M | E5: 44 | F5: 108 | G5: 33 | H5: 44 | I5: 0 | J5: 0 | K5: 0 | L5: 0 | M5: 0 | Q5: 動作周波数 | R5: 14.653 | S5: [MHz]
C6: MMCAM | E6: 745 | F6: 1342 | G6: 428 | H6: 745 | I6: 0 | J6: 0 | K6: 0 | L6: 0 | M6: 0 | P6: PS～MA | Q6: ステージ通過パケット数 | R6: 62 | S6: [Packet]
C7: MMRAM | E7: 162 | F7: 54 | G7: 60 | H7: 162 | I7: 1 | J7: 0 | K7: 0 | L7: 0 | M7: 0 | Q7: 動作周期 | R7: =R2/R6 -> 81.451613 | S7: [ns]
C8: PS | E8: 1 | F8: 84 | G8: 21 | H8: 1 | I8: 0.5 | J8: 0 | K8: 0 | L8: 0 | M8: 0 | Q8: 動作周波数 | R8: 12.27722 | S8: [MHz]
C9: FP | E9: 1344 | F9: 94 | G9: 361 | H9: 1344 | I9: 0 | J9: 4 | K9: 0 | L9: 0 | M9: 0 | P9: COPY～B | Q9: ステージ通過パケット数 | R9: 74 | S9: [Packet]
C10: MA | E10: 83 | F10: 57 | G10: 64 | H10: 83 | I10: 1 | J10: 0 | K10: 0 | L10: 0 | M10: 0 | Q10: 動作周期 | R10: =R2/R3 -> 68.243243 | S10: [ns]
C11: COPY | E11: 15 | F11: 56 | G11: 12 | H11: 15 | I11: 0 | J11: 0 | K11: 0 | L11: 0 | M11: 0 | Q11: 動作周波数 | R11: 14.653 | S11: [MHz]
C12: B | E12: 0 | F12: 54 | G12: 12 | H12: 0 | I12: 0.5 | J12: 0 | K12: 0 | L12: 0 | M12: 0
C13: C_output
C14: CC | E14: 364 | F14: 11 | G14: 110 | H14: 364 | I14: 0 | J14: 0 | K14: 0 | L14: 0 | M14: 0
D15: m | E15: 89 | F15: 0 | G15: 38 | H15: 89 | I15: 0 | J15: 0 | K15: 0 | L15: 0 | M15: 0
D16: mmcam | E16: 32 | F16: 0 | G16: 11 | H16: 32 | I16: 0 | J16: 0 | K16: 0 | L16: 0 | M16: 0
D17: mmram | E17: 29 | F17: 1 | G17: 10 | H17: 29 | I17: 0 | J17: 0 | K17: 0 | L17: 0 | M17: 0
D18: ps | E18: 35 | F18: 0 | G18: 10 | H18: 35 | I18: 0 | J18: 0 | K18: 0 | L18: 0 | M18: 0
D19: fp | E19: 31 | F19: 1 | G19: 12 | H19: 31 | I19: 0 | J19: 0 | K19: 0 | L19: 0 | M19: 0
D20: ma | E20: 42 | F20: 0 | G20: 15 | H20: 42 | I20: 0 | J20: 0 | K20: 0 | L20: 0 | M20: 0
D21: copy | E21: 54 | F21: 8 | G21: 17 | H21: 54 | I21: 0 | J21: 0 | K21: 0 | L21: 0 | M21: 0
D22: b | E22: 35 | F22: 1 | G22: 16 | H22: 35 | I22: 0 | J22: 0 | K22: 0 | L22: 0 | M22: 0
B26: ddp1 | E26: 2743 | F26: 1914 | G26: 1022 | H26: 2743 | I26: 3 | J26: 4 | K26: 0 | L26: 0 | M26: 0
C27: M | E27: 44 | F27: 108 | G27: 30 | H27: 44 | I27: 0 | J27: 0 | K27: 0 | L27: 0 | M27: 0
C28: MMCAM | E28: 745 | F28: 1342 | G28: 434 | H28: 745 | I28: 0 | J28: 0 | K28: 0 | L28: 0 | M28: 0
C29: MMRAM | E29: 158 | F29: 54 | G29: 56 | H29: 158 | I29: 1 | J29: 0 | K29: 0 | L29: 0 | M29: 0
C30: PS | E30: 1 | F30: 84 | G30: 19 | H30: 1 | I30: 0.5 | J30: 0 | K30: 0 | L30: 0 | M30: 0
C31: FP | E31: 1351 | F31: 94 | G31: 373 | H31: 1351 | I31: 4 | J31: 0 | K31: 0 | L31: 0 | M31: 0
C32: MA | E32: 87 | F32: 57 | G32: 58 | H32: 87 | I32: 1 | J32: 0 | K32: 0 | L32: 0 | M32: 0
C33: COPY | E33: 16 | F33: 56 | G33: 14 | H33: 16 | I33: 0 | J33: 0 | K33: 0 | L33: 0 | M33: 0
C34: B | E34: 0 | F34: 54 | G34: 12 | H34: 0 | I34: 0.5 | J34: 0 | K34: 0 | L34: 0 | M34: 0
C35: C_output | K35: 0 | L35: 0 | M35: 0
C36: CC | E36: 340 | F36: 11 | G36: 97 | H36: 340 | I36: 0 | J36: 0 | K36: 0 | L36: 0 | M36: 0
D37: m | E37: 80 | F37: 0 | G37: 24 | H37: 80 | I37: 0 | J37: 0 | K37: 0 | L37: 0 | M37: 0
D38: mmcam | E38: 32 | F38: 0 | G38: 9 | H38: 32 | I38: 0 | J38: 0 | K38: 0 | L38: 0 | M38: 0
D39: mmram | E39: 29 | F39: 1 | G39: 12 | H39: 29 | I39: 0 | J39: 0 | K39: 0 | L39: 0 | M39: 0
D40: ps | E40: 35 | F40: 0 | G40: 12 | H40: 35 | I40: 0 | J40: 0 | K40: 0 | L40: 0 | M40: 0
D41: fp | E41: 28 | F41: 1 | G41: 11 | H41: 28 | I41: 0 | J41: 0 | K41: 0 | L41: 0 | M41: 0
D42: ma | E42: 39 | F42: 0 | G42: 12 | H42: 39 | I42: 0 | J42: 0 | K42: 0 | L42: 0 | M42: 0
D43: copy | E43: 66 | F43: 8 | G43: 22 | H43: 66 | I43: 0 | J43: 0 | K43: 0 | L43: 0 | M43: 0
...

Sheet Power estimation model
A1: ModelType | D1: X1 | E1: X2 | F1: X3 | G1: 切片（others）
A2: 試作モデル | B2: X1f+X2LUT+X3REG | D2: =Async回路回帰分析_グラフ出力!L107 -> 0.0039442682 | E2: =Async回路回帰分析_グラフ出力!L108 -> 5.6356442e-06 | F2: =Async回路回帰分析_グラフ出力!L109 -> 1.3464873e-05 | G2: =Async回路回帰分析_グラフ出力!L106 -> 1.3531911
A3: 提案モデルA | B3: (P-1.49)/f =X1NL+X2NR+Pothers | D3: =Async回路回帰分析_グラフ出力!B193 -> 1.8996082e-13 | E3: =Async回路回帰分析_グラフ出力!B194 -> 4.6329777e-13 | G3: =Async回路回帰分析_グラフ出力!B192 -> -7.0054889e-10
A4: 提案モデルB | B4: X1f(X2LUT+X3REG) | D4: =Async回路回帰分析_グラフ出力!L132 -> 2.132286e-07 | G4: =Async回路回帰分析_グラフ出力!L131 -> 1.48094
B6: FIRーDDPプログラム | C6: 周波数[MHz] | D6: LUT | E6: Reg | F6: 待機時電力 | G6: 試作モデル | H6: 提案モデルA | I6: 提案モデルB（f*(LUT+Reg)） | J6: 提案モデルB補正 | K6: X1*提案モデルB | L6: 実測電力 | N6: 簡単な乗算プログラム | O6: 実測電力 | P6: 周波数 | Q6: 提案モデルA | R6: 提案モデルB
A7: DDP16bit | B7: DDP | C7: =DDP_Datasheet_16bit!$R$5 -> 14.653 | D7: 1987 | E7: 2757 | F7: =DDP_Datasheet_16bit!D167 -> 1.4647581 | G7: =C7*$D$2+D7*$E$2+E7*$F$2 -> 0.10611604 | L7: =DDP_Datasheet_16bit!C167 -> 1.5057903 | N7: DDP | O7: =DDP_Datasheet_16bit!$G$167 -> 1.5900484 | P7: 20
B8: M | C8: =DDP_Datasheet_16bit!$R$5 -> 14.653 | D8: =DDP_Datasheet_16bit!E5+DDP_Datasheet_16bit!E15 -> 120 | E8: =DDP_Datasheet_16bit!F5+DDP_Datasheet_16bit!F15 -> 76 | G8: =C8*$D$2+D8*$E$2+E8*$F$2 -> 0.05949497 | H8: =C8*10^6*(D8*$D$3+E8*$E$3) -> 0.00084996089 | I8: =(C8*(D8+E8)) -> 2871.988 | K8: =I8*$D$4 -> 0.00061238998 | N8: M | P8: 20 | Q8: =P8*10^6*(D8*$D$3+E8*$E$3) -> 0.0011601186 | R8: =(P8*(D8+E8))*$D$4 -> 0.00083585611
B9: MMCAM | C9: =DDP_Datasheet_16bit!$R$5 -> 14.653 | D9: =DDP_Datasheet_16bit!E6+DDP_Datasheet_16bit!E16 -> 780 | E9: =DDP_Datasheet_16bit!F6+DDP_Datasheet_16bit!F16 -> 1326 | G9: =C9*$D$2+D9*$E$2+E9*$F$2 -> 0.080045586 | H9: =C9*10^6*(D9*$D$3+E9*$E$3) -> 0.011172946 | I9: =(C9*(D9+E9)) -> 30859.218 | K9: =I9*$D$4 -> 0.0065800678 | N9: MMCAM | P9: 20 | Q9: =P9*10^6*(D9*$D$3+E9*$E$3) -> 0.015250046 | R9: =(P9*(D9+E9))*$D$4 -> 0.0089811886
B10: MMRAM | C10: =DDP_Datasheet_16bit!$R$5 -> 14.653 | D10: =DDP_Datasheet_16bit!E7+DDP_Datasheet_16bit!E17 -> 130 | E10: =DDP_Datasheet_16bit!F7+DDP_Datasheet_16bit!F17 -> 39 | G10: =C10*$D$2+D10*$E$2+E10*$F$2 -> 0.059053126 | H10: =C10*10^6*(D10*$D$3+E10*$E$3) -> 0.00062661386 | I10: =(C10*(D10+E10)) -> 2476.357 | K10: =I10*$D$4 -> 0.00052803013 | N10: MMRAM | P10: 20 | Q10: =P10*10^6*(D10*$D$3+E10*$E$3) -> 0.00085527041 | R10: =(P10*(D10+E10))*$D$4 -> 0.00072071266
B11: PS | C11: =DDP_Datasheet_16bit!$R$8 -> 12.27722 | D11: =DDP_Datasheet_16bit!E8+DDP_Datasheet_16bit!E18 -> 36 | E11: =DDP_Datasheet_16bit!F8+DDP_Datasheet_16bit!F18 -> 52 | G11: =C11*$D$2+D11*$E$2+E11*$F$2 -> 0.049327705 | H11: =C11*10^6*(D11*$D$3+E11*$E$3) -> 0.00037973532 | I11: =(C11*(D11+E11)) -> 1080.3954 | K11: =I11*$D$4 -> 0.00023037119 | N11: PS | P11: 20 | Q11: =P11*10^6*(D11*$D$3+E11*$E$3) -> 0.00061860148 | R11: =(P11*(D11+E11))*$D$4 -> 0.00037528233
B12: FP | C12: =DDP_Datasheet_16bit!$R$8 -> 12.27722 | D12: =DDP_Datasheet_16bit!E9+DDP_Datasheet_16bit!E19 -> 686 | E12: =DDP_Datasheet_16bit!F9+DDP_Datasheet_16bit!F19 -> 63 | G12: =C12*$D$2+D12*$E$2+E12*$F$2 -> 0.053138987 | H12: =C12*10^6*(D12*$D$3+E12*$E$3) -> 0.0019582275 | I12: =(C12*(D12+E12)) -> 9195.6378 | K12: =I12*$D$4 -> 0.001960773 | N12: FP | P12: 20 | Q12: =P12*10^6*(D12*$D$3+E12*$E$3) -> 0.0031900177 | R12: =(P12*(D12+E12))*$D$4 -> 0.0031941644
B13: MA | C13: =DDP_Datasheet_16bit!$R$8 -> 12.27722 | D13: =DDP_Datasheet_16bit!E10+DDP_Datasheet_16bit!E20 -> 105 | E13: =DDP_Datasheet_16bit!F10+DDP_Datasheet_16bit!F20 -> 41 | F13: =C13*10^6*E13*E3 -> 0.00023320836 | G13: =C13*$D$2+D13*$E$2+E13*$F$2 -> 0.049568451 | H13: =C13*10^6*(D13*$D$3+E13*$E$3) -> 0.00047808839 | I13: =(C13*(D13+E13)) -> 1792.4741 | J13: =(C13*(E13)) -> 503.36602 | K13: =J13*$D$4 -> 0.00010733203 | N13: MA | P13: 20 | Q13: =P13*10^6*(D13*$D$3+E13*$E$3) -> 0.0007788219 | R13: =(P13*(D13+E13))*$D$4 -> 0.00062262751
B14: COPY | C14: =DDP_Datasheet_16bit!$R$5 -> 14.653 | D14: =DDP_Datasheet_16bit!E11+DDP_Datasheet_16bit!E21 -> 75 | E14: =DDP_Datasheet_16bit!F11+DDP_Datasheet_16bit!F21 -> 48 | G14: =C14*$D$2+D14*$E$2+E14*$F$2 -> 0.058864349 | H14: =C14*10^6*(D14*$D$3+E14*$E$3) -> 0.00053461991 | I14: =(C14*(D14+E14)) -> 1802.319 | K14: =I14*$D$4 -> 0.00038430595 | N14: COPY | P14: 20 | Q14: =P14*10^6*(D14*$D$3+E14*$E$3) -> 0.0007297071 | R14: =(P14*(D14+E14))*$D$4 -> 0.00052454235
B15: B | C15: =DDP_Datasheet_16bit!$R$5 -> 14.653 | D15: =DDP_Datasheet_16bit!E12+DDP_Datasheet_16bit!E22 -> 34 | E15: =DDP_Datasheet_16bit!F12+DDP_Datasheet_16bit!F22 -> 39 | G15: =C15*$D$2+D15*$E$2+E15*$F$2 -> 0.058512104 | H15: =C15*10^6*(D15*$D$3+E15*$E$3) -> 0.00035939825 | I15: =(C15*(D15+E15)) -> 1069.669 | K15: =I15*$D$4 -> 0.00022808402 | N15: B | P15: 20 | Q15: =P15*10^6*(D15*$D$3+E15*$E$3) -> 0.00049054562 | R15: =(P15*(D15+E15))*$D$4 -> 0.00031131375
B16: Total | D16: =SUM(D8:D15) -> 1966 | E16: =SUM(E8:E15) -> 1684 | G16: =SUM(G8:G15) -> 0.46800528 | H16: =SUM(H8:H15) -> 0.01635959 | K16: =SUM(K8:K15) -> 0.010631354 | N16: Total | Q16: =SUM(Q8:Q15) -> 0.023073129 | R16: =SUM(R8:R15) -> 0.015565688
B17: ＊４ | G17: =G16*4 -> 1.8720211 | H17: =H16*4 -> 0.065438361 | K17: =K16*4 -> 0.042525416 | N17: ＊４ | Q17: =Q16*4 -> 0.092292515 | R17: =R16*4 -> 0.062262751
B18: "+"others | G18: =G17+G2 -> 3.2252122 | H18: =H17+G3+1.49 -> 1.5554384 | K18: =G4+K17 -> 1.5234654 | N18: "+"others | Q18: =Q$17+$G$3+1.49 -> 1.5822925 | R18: =R$17+$G$4 -> 1.5432027
B19: 実測値との差 | G19: =L7-G18 -> -1.7194219 | H19: =L7-H18 -> -0.049648037 | K19: =L7-K18 -> -0.01767508 | N19: 実測値との差 | Q19: =O7-Q18 -> 0.0077558733 | R19: =O7-R18 -> 0.04684565
B20: 絶対誤差 | G20: =(G18-$L$7)/L7*100 -> 114.18734 | H20: =(H18-$L$7)/$L$7*100 -> 3.2971415 | K20: =(K18-$L$7)/$L$7*100 -> 1.1738075 | N20: 絶対誤差 | Q20: =(Q18-O7)/O7*100 -> -0.48777593 | R20: =(R18-O7)/O7*100 -> -2.9461776
C25: 周波数[MHz] | D25: LUT | E25: Reg | F25: 待機時電力 | G25: 試作モデル | H25: 提案モデルA | I25: 提案モデルB（f*(LUT+Reg)） | J25: 提案モデルB補正 | K25: X1*提案モデルB | L25: 実測値 | N25: 簡単な乗算プログラム | O25: 実測電力 | P25: 周波数 | Q25: 提案モデルA | R25: 提案モデルB
